Workbook
Name Slicer_Month_Name: #N/A
Name Slicer_Month_Year: #N/A
Name Slicer_Ticket_Status: #N/A
Name Slicer_Ticket_Type: #N/A

Sheet Working data
A1: Ticket ID | B1: Customer Name | C1: Customer Email | D1: Customer Age | E1: Customer Gender | F1: Product Purchased | G1: Date of Purchase | H1: Ticket Type | I1: Ticket Subject | J1: Ticket Description | K1: Ticket Status | L1: Resolution | M1: Ticket Priority | N1: Ticket Channel | O1: First Response Time | P1: Time to Resolution | Q1: Customer Satisfaction Rating | R1: Row check | S1: Resolution Clean | T1: Customer_Name_Clean | U1: Month_Number | V1: Month_Name | W1: Month_Year | X1: Resolution Time (Hours)
A2: 1 | B2: Marisa Obrien | C2: carrollallison@example.com | D2: 32 | E2: Other | F2: GoPro Hero | G2: 44277 | H2: Technical issue | I2: Product setup | J2: I'm having an issue with the {product_purchased}. Please assist. Your billing zip code is: 71701. We appreciate that you have requested a website address. Please double check your email address. I've tried troubleshooting steps mentioned in the user manual, but the issue persists. | K2: Pending Customer Response | M2: Critical | N2: Social media | O2: 45078.511 | R2: 1 | S2: =PROPER(CustomerSupport[[#This Row],[Resolution]]) | T2: =TRIM(CustomerSupport[[#This Row],[Customer Name]]) -> Marisa Obrien | U2: =MONTH(CustomerSupport[[#This Row],[Date of Purchase]]) -> 3 | V2: =TEXT('Working data'!G2,"mmmm") -> March | W2: =YEAR(CustomerSupport[[#This Row],[Date of Purchase]]) -> 2021 | X2: =IF(OR(O2="",P2=""),"",(P2-O2)*24)
A3: 2 | B3: Jessica Rios | C3: clarkeashley@example.com | D3: 42 | E3: Female | F3: LG Smart TV | G3: 44338 | H3: Technical issue | I3: Peripheral compatibility | J3: I'm having an issue with the {product_purchased}. Please assist. If you need to change an existing product. I'm having an issue with the {product_purchased}. Please assist. If The issue I'm facing is intermittent. Sometimes it works fine, but other times it acts up unexpectedly. | K3: Pending Customer Response | M3: Critical | N3: Chat | O3: 45078.698 | R3: 2 | S3: =PROPER(CustomerSupport[[#This Row],[Resolution]]) | T3: =TRIM(CustomerSupport[[#This Row],[Customer Name]]) -> Jessica Rios | U3: =MONTH(CustomerSupport[[#This Row],[Date of Purchase]]) -> 5 | V3: =TEXT('Working data'!G3,"mmmm") -> May | W3: =YEAR(CustomerSupport[[#This Row],[Date of Purchase]]) -> 2021 | X3: =IF(OR(O3="",P3=""),"",(P3-O3)*24)
A4: 3 | B4: Christopher Robbins | C4: gonzalestracy@example.com | D4: 48 | E4: Other | F4: Dell XPS | G4: 44026 | H4: Technical issue | I4: Network problem | J4: I'm facing a problem with my {product_purchased}. The {product_purchased} is not turning on. It was working fine until yesterday, but now it doesn't respond. 1.8.3 I really I'm using the original charger that came with my {product_purchased}, but it's not charging properly. | K4: Closed | L4: Case maybe show recently my computer follow. | M4: Low | N4: Social media | O4: 45078.468 | P4: 45078.754 | Q4: 3 | R4: 3 | S4: =PROPER(CustomerSupport[[#This Row],[Resolution]]) -> Case Maybe Show Recently My Computer Follow. | T4: =TRIM(CustomerSupport[[#This Row],[Customer Name]]) -> Christopher Robbins | U4: =MONTH(CustomerSupport[[#This Row],[Date of Purchase]]) -> 7 | V4: =TEXT('Working data'!G4,"mmmm") -> July | W4: =YEAR(CustomerSupport[[#This Row],[Date of Purchase]]) -> 2020 | X4: =IF(OR(O4="",P4=""),"",(P4-O4)*24) -> 6.85
A5: 4 | B5: Christina Dillon | C5: bradleyolson@example.org | D5: 27 | E5: Female | F5: Microsoft Office | G5: 44148 | H5: Billing inquiry | I5: Account access | J5: I'm having an issue with the {product_purchased}. Please assist. If you have a problem you're interested in and I'd love to see this happen, please check out the Feedback. I've already contacted customer support multiple times, but the issue remains unresolved. | K5: Closed | L5: Try capital clearly never color toward story. | M5: Low | N5: Social media | O5: 45078.312 | P5: 45078.082 | Q5: 3 | R5: 4 | S5: =PROPER(CustomerSupport[[#This Row],[Resolution]]) -> Try Capital Clearly Never Color Toward Story. | T5: =TRIM(CustomerSupport[[#This Row],[Customer Name]]) -> Christina Dillon | U5: =MONTH(CustomerSupport[[#This Row],[Date of Purchase]]) -> 11 | V5: =TEXT('Working data'!G5,"mmmm") -> November | W5: =YEAR(CustomerSupport[[#This Row],[Date of Purchase]]) -> 2020 | X5: =IF(OR(O5="",P5=""),"",(P5-O5)*24) -> -5.5333333
A6: 5 | B6: Alexander Carroll | C6: bradleymark@example.com | D6: 67 | E6: Female | F6: Autodesk AutoCAD | G6: 43865 | H6: Billing inquiry | I6: Data loss | J6: I'm having an issue with the {product_purchased}. Please assist. Note: The seller is not responsible for any damages arising out of the delivery of the battleground game. Please have the game in good condition and shipped to you I've noticed a sudden decrease in battery life on my {product_purchased}. It used to last much longer. | K6: Closed | L6: West decision evidence bit. | M6: Low | N6: Email | O6: 45078.009 | P6: 45078.829 | Q6: 1 | R6: 5 | S6: =PROPER(CustomerSupport[[#This Row],[Resolution]]) -> West Decision Evidence Bit. | T6: =TRIM(CustomerSupport[[#This Row],[Customer Name]]) -> Alexander Carroll | U6: =MONTH(CustomerSupport[[#This Row],[Date of Purchase]]) -> 2 | V6: =TEXT('Working data'!G6,"mmmm") -> February | W6: =YEAR(CustomerSupport[[#This Row],[Date of Purchase]]) -> 2020 | X6: =IF(OR(O6="",P6=""),"",(P6-O6)*24) -> 19.683333
A7: 6 | B7: Rebecca Fleming | C7: sheenasmith@example.com | D7: 53 | E7: Male | F7: Microsoft Office | G7: 44040 | H7: Cancellation request | I7: Payment issue | J7: I'm facing a problem with my {product_purchased}. The {product_purchased} is not turning on. It was working fine until yesterday, but now it doesn't respond. To remove the new {product_purch I've checked for any available software updates for my {product_purchased}, but there are none. | K7: Open | M7: Low | N7: Social media | R7: 6 | S7: =PROPER(CustomerSupport[[#This Row],[Resolution]]) | T7: =TRIM(CustomerSupport[[#This Row],[Customer Name]]) -> Rebecca Fleming | U7: =MONTH(CustomerSupport[[#This Row],[Date of Purchase]]) -> 7 | V7: =TEXT('Working data'!G7,"mmmm") -> July | W7: =YEAR(CustomerSupport[[#This Row],[Date of Purchase]]) -> 2020 | X7: =IF(OR(O7="",P7=""),"",(P7-O7)*24)
A8: 7 | B8: Jacqueline Wright | C8: donaldkeith@example.org | D8: 24 | E8: Other | F8: Microsoft Surface | G8: 43884 | H8: Product inquiry | I8: Refund request | J8: I'm unable to access my {product_purchased} account. It keeps displaying an 'Invalid Credentials' error, even though I'm using the correct login information. How can I regain access to my account? Solution 1 I'm unable to find the option to perform the desired action in the {product_purchased}. Could you please guide me through the steps? | K8: Open | M8: Critical | N8: Social media | R8: 7 | S8: =PROPER(CustomerSupport[[#This Row],[Resolution]]) | T8: =TRIM(CustomerSupport[[#This Row],[Customer Name]]) -> Jacqueline Wright | U8: =MONTH(CustomerSupport[[#This Row],[Date of Purchase]]) -> 2 | V8: =TEXT('Working data'!G8,"mmmm") -> February | W8: =YEAR(CustomerSupport[[#This Row],[Date of Purchase]]) -> 2020 | X8: =IF(OR(O8="",P8=""),"",(P8-O8)*24)
A9: 8 | B9: Denise Lee | C9: joelwilliams@example.com | D9: 23 | E9: Male | F9: Philips Hue Lights | G9: 44052 | H9: Refund request | I9: Battery life | J9: I'm having an issue with the {product_purchased}. Please assist. (Thanks) I will contact all my suppliers and confirm. Please try and find out whether their inventory is currently stocked, or any other reason. I am I've performed a factory reset on my {product_purchased}, hoping it would resolve the problem, but it didn't help. | K9: Open | M9: Critical | N9: Social media | R9: 8 | S9: =PROPER(CustomerSupport[[#This Row],[Resolution]]) | T9: =TRIM(CustomerSupport[[#This Row],[Customer Name]]) -> Denise Lee | U9: =MONTH(CustomerSupport[[#This Row],[Date of Purchase]]) -> 8 | V9: =TEXT('Working data'!G9,"mmmm") -> August | W9: =YEAR(CustomerSupport[[#This Row],[Date of Purchase]]) -> 2020 | X9: =IF(OR(O9="",P9=""),"",(P9-O9)*24)
A10: 9 | B10: Nicolas Wilson | C10: joshua24@example.com | D10: 60 | E10: Other | F10: Fitbit Versa Smartwatch | G10: 44028 | H10: Technical issue | I10: Installation support | J10: I'm having an issue with the {product_purchased}. Please assist. Thank you. {product_purchased} is not the exact type you might prefer, they use the exact same method for different uses. Please help I've recently updated the firmware of my {product_purchased}, and the issue started happening afterward. Could it be related to the update? | K10: Pending Customer Response | M10: Low | N10: Social media | O10: 45078.439 | R10: 9 | S10: =PROPER(CustomerSupport[[#This Row],[Resolution]]) | T10: =TRIM(CustomerSupport[[#This Row],[Customer Name]]) -> Nicolas Wilson | U10: =MONTH(CustomerSupport[[#This Row],[Date of Purchase]]) -> 7 | V10: =TEXT('Working data'!G10,"mmmm") -> July | W10: =YEAR(CustomerSupport[[#This Row],[Date of Purchase]]) -> 2020 | X10: =IF(OR(O10="",P10=""),"",(P10-O10)*24)
A11: 10 | B11: William Dawson | C11: clopez@example.com | D11: 27 | E11: Male | F11: Dyson Vacuum Cleaner | G11: 43896 | H11: Refund request | I11: Payment issue | J11: My {product_purchased} is making strange noises and not functioning properly. I suspect there might be a hardware issue. Can you please help me with this? } If we can, please send a "request" to dav The issue I'm facing is intermittent. Sometimes it works fine, but other times it acts up unexpectedly. | K11: Pending Customer Response | M11: Critical | N11: Phone | O11: 45078.393 | R11: 10 | S11: =PROPER(CustomerSupport[[#This Row],[Resolution]]) | T11: =TRIM(CustomerSupport[[#This Row],[Customer Name]]) -> William Dawson | U11: =MONTH(CustomerSupport[[#This Row],[Date of Purchase]]) -> 3 | V11: =TEXT('Working data'!G11,"mmmm") -> March | W11: =YEAR(CustomerSupport[[#This Row],[Date of Purchase]]) -> 2020 | X11: =IF(OR(O11="",P11=""),"",(P11-O11)*24)
A12: 11 | B12: Joseph Moreno | C12: mbrown@example.org | D12: 48 | E12: Male | F12: Nintendo Switch | G12: 44215 | H12: Cancellation request | I12: Data loss | J12: I'm having an issue with the {product_purchased}. Please assist. 1-800-799-0808. Product Search: What's New in 2-3-4-5? Report Feedback Customer Service is your best I'm using the original charger that came with my {product_purchased}, but it's not charging properly. | K12: Closed | L12: Measure tonight surface feel forward. | M12: High | N12: Phone | O12: 45078.741 | P12: 45077.994 | Q12: 1 | R12: 11 | S12: =PROPER(CustomerSupport[[#This Row],[Resolution]]) -> Measure Tonight Surface Feel Forward. | T12: =TRIM(CustomerSupport[[#This Row],[Customer Name]]) -> Joseph Moreno | U12: =MONTH(CustomerSupport[[#This Row],[Date of Purchase]]) -> 1 | V12: =TEXT('Working data'!G12,"mmmm") -> January | W12: =YEAR(CustomerSupport[[#This Row],[Date of Purchase]]) -> 2021 | X12: =IF(OR(O12="",P12=""),"",(P12-O12)*24) -> -17.916667
A13: 12 | B13: Brandon Arnold | C13: davisjohn@example.net | D13: 51 | E13: Male | F13: Microsoft Xbox Controller | G13: 44493 | H13: Product inquiry | I13: Software bug | J13: I'm having an issue with the {product_purchased}. Please assist. 4. It is possible that we cannot find some type of text or a product name to identify someone like Mr. Brown. 5. On the I've reviewed the troubleshooting steps on the official support website, but they didn't resolve the problem. | K13: Closed | L13: Measure there house management pick knowledge trade. | M13: High | N13: Chat | O13: 45078.504 | P13: 45078.394 | Q13: 1 | R13: 12 | S13: =PROPER(CustomerSupport[[#This Row],[Resolution]]) -> Measure There House Management Pick Knowledge Trade. | T13: =TRIM(CustomerSupport[[#This Row],[Customer Name]]) -> Brandon Arnold | U13: =MONTH(CustomerSupport[[#This Row],[Date of Purchase]]) -> 10 | V13: =TEXT('Working data'!G13,"mmmm") -> October | W13: =YEAR(CustomerSupport[[#This Row],[Date of Purchase]]) -> 2021 | X13: =IF(OR(O13="",P13=""),"",(P13-O13)*24) -> -2.6333333
A14: 13 | B14: Tamara Hahn | C14: jensenwilliam@example.net | D14: 27 | E14: Other | F14: Nintendo Switch Pro Controller | G14: 44342 | H14: Technical issue | I14: Hardware issue | J14: I'm having an issue with the {product_purchased}. Please assist. CQW: Why didn't I send him the invoice? Thanks a lot. L: He's like the best customer I've met. I've noticed that the issue occurs consistently when I use a specific feature or application on my {product_purchased}. | K14: Pending Customer Response | M14: Low | N14: Chat | O14: 45078.794 | R14: 13 | S14: =PROPER(CustomerSupport[[#This Row],[Resolution]]) | T14: =TRIM(CustomerSupport[[#This Row],[Customer Name]]) -> Tamara Hahn | U14: =MONTH(CustomerSupport[[#This Row],[Date of Purchase]]) -> 5 | V14: =TEXT('Working data'!G14,"mmmm") -> May | W14: =YEAR(CustomerSupport[[#This Row],[Date of Purchase]]) -> 2021 | X14: =IF(OR(O14="",P14=""),"",(P14-O14)*24)
A15: 14 | B15: Sandra Barnes | C15: gwendolyn51@example.net | D15: 65 | E15: Other | F15: Nest Thermostat | G15: 44025 | H15: Technical issue | I15: Product setup | J15: I've recently set up my {product_purchased}, but it fails to connect to any available networks. What steps should I take to troubleshoot this issue? I can't find the 'Product_IP' field of the I'm concerned about the security of my {product_purchased} and would like to ensure that my data is safe. | K15: Pending Customer Response | M15: Low | N15: Chat | O15: 45078.858 | R15: 14 | S15: =PROPER(CustomerSupport[[#This Row],[Resolution]]) | T15: =TRIM(CustomerSupport[[#This Row],[Customer Name]]) -> Sandra Barnes | U15: =MONTH(CustomerSupport[[#This Row],[Date of Purchase]]) -> 7 | V15: =TEXT('Working data'!G15,"mmmm") -> July | W15: =YEAR(CustomerSupport[[#This Row],[Date of Purchase]]) -> 2020 | X15: =IF(OR(O15="",P15=""),"",(P15-O15)*24)
A16: 15 | B16: Amy Hill | C16: medinasteven@example.net | D16: 48 | E16: Female | F16: Sony PlayStation | G16: 43890 | H16: Billing inquiry | I16: Product setup | J16: I'm having an issue with the {product_purchased}. Please assist. Product Name: TPUBASK3E3KQ0 Join Date: Oct 2007 Posts: 11,532 Quote: I've recently updated the firmware of my {product_purchased}, and the issue started happening afterward. Could it be related to the update? | K16: Closed | L16: Officer moment world sing parent available. | M16: High | N16: Chat | O16: 45078.266 | P16: 45077.965 | Q16: 4 | R16: 15 | S16: =PROPER(CustomerSupport[[#This Row],[Resolution]]) -> Officer Moment World Sing Parent Available. | T16: =TRIM(CustomerSupport[[#This Row],[Customer Name]]) -> Amy Hill | U16: =MONTH(CustomerSupport[[#This Row],[Date of Purchase]]) -> 2 | V16: =TEXT('Working data'!G16,"mmmm") -> February | W16: =YEAR(CustomerSupport[[#This Row],[Date of Purchase]]) -> 2020 | X16: =IF(OR(O16="",P16=""),"",(P16-O16)*24) -> -7.2333333
A17: 16 | B17: Elizabeth Foley | C17: amy41@example.net | D17: 18 | E17: Other | F17: GoPro Action Camera | G17: 44371 | H17: Billing inquiry | I17: Product recommendation | J17: I'm having an issue with the {product_purchased}. Please assist. Please note, you might have already paid for this product, which means spectators are not buying any of the products from the sale as their donations will go straight I've noticed a sudden decrease in battery life on my {product_purchased}. It used to last much longer. | K17: Pending Customer Response | M17: High | N17: Social media | O17: 45078.632 | R17: 16 | S17: =PROPER(CustomerSupport[[#This Row],[Resolution]]) | T17: =TRIM(CustomerSupport[[#This Row],[Customer Name]]) -> Elizabeth Foley | U17: =MONTH(CustomerSupport[[#This Row],[Date of Purchase]]) -> 6 | V17: =TEXT('Working data'!G17,"mmmm") -> June | W17: =YEAR(CustomerSupport[[#This Row],[Date of Purchase]]) -> 2021 | X17: =IF(OR(O17="",P17=""),"",(P17-O17)*24)
A18: 17 | B18: Julia Salazar | C18: watkinsbarbara@example.com | D18: 63 | E18: Other | F18: Xbox | G18: 44482 | H18: Product inquiry | I18: Account access | J18: I'm having an issue with the {product_purchased}. Please assist. - Acknowledgement: Thanks to Dan for the tip. When you purchase a new product from my store or from your local retailer, they will also provide I'm concerned about the security of my {product_purchased} and would like to ensure that my data is safe. | K18: Closed | L18: Seek evidence book collection catch. | M18: Critical | N18: Chat | O18: 45078.824 | P18: 45078.666 | Q18: 4 | R18: 17 | S18: =PROPER(CustomerSupport[[#This Row],[Resolution]]) -> Seek Evidence Book Collection Catch. | T18: =TRIM(CustomerSupport[[#This Row],[Customer Name]]) -> Julia Salazar | U18: =MONTH(CustomerSupport[[#This Row],[Date of Purchase]]) -> 10 | V18: =TEXT('Working data'!G18,"mmmm") -> October | W18: =YEAR(CustomerSupport[[#This Row],[Date of Purchase]]) -> 2021 | X18: =IF(OR(O18="",P18=""),"",(P18-O18)*24) -> -3.8
A19: 18 | B19: Joshua Castillo | C19: mooredeborah@example.org | D19: 56 | E19: Female | F19: Microsoft Xbox Controller | G19: 44081 | H19: Product inquiry | I19: Payment issue | J19: I'm having an issue with the {product_purchased}. Please assist. Thanks!" * [0] - [0] - [0] - [0] If this product is sold and you have not used any I've reviewed the troubleshooting steps on the official support website, but they didn't resolve the problem. | K19: Pending Customer Response | M19: High | N19: Chat | O19: 45078.878 | R19: 18 | S19: =PROPER(CustomerSupport[[#This Row],[Resolution]]) | T19: =TRIM(CustomerSupport[[#This Row],[Customer Name]]) -> Joshua Castillo | U19: =MONTH(CustomerSupport[[#This Row],[Date of Purchase]]) -> 9 | V19: =TEXT('Working data'!G19,"mmmm") -> September | W19: =YEAR(CustomerSupport[[#This Row],[Date of Purchase]]) -> 2020 | X19: =IF(OR(O19="",P19=""),"",(P19-O19)*24)
A20: 19 | B20: Wendy Davis | C20: brenda20@example.net | D20: 19 | E20: Male | F20: LG Washing Machine | G20: 44462 | H20: Product inquiry | I20: Peripheral compatibility | J20: I'm having an issue with the {product_purchased}. Please assist. I want to be an active member of our community on YouTube... The issue I'm facing is intermittent. Sometimes it works fine, but other times it acts up unexpectedly. | K20: Open | M20: High | N20: Social media | R20: 19 | S20: =PROPER(CustomerSupport[[#This Row],[Resolution]]) | T20: =TRIM(CustomerSupport[[#This Row],[Customer Name]]) -> Wendy Davis | U20: =MONTH(CustomerSupport[[#This Row],[Date of Purchase]]) -> 9 | V20: =TEXT('Working data'!G20,"mmmm") -> September | W20: =YEAR(CustomerSupport[[#This Row],[Date of Purchase]]) -> 2021 | X20: =IF(OR(O20="",P20=""),"",(P20-O20)*24)
A21: 20 | B21: Jeffrey Robertson | C21: jameslopez@example.com | D21: 39 | E21: Female | F21: Canon EOS | G21: 44263 | H21: Refund request | I21: Software bug | J21: I'm having an issue with the {product_purchased}. Please assist. I'm having an issue with the product_purchased}. Please assist. Customer Reviewer: My Husband was able to take an order from Apple I've checked for any available software updates for my {product_purchased}, but there are none. | K21: Closed | L21: Wish mouth build resource though. | M21: Low | N21: Chat | O21: 45078.032 | P21: 45078.854 | Q21: 5 | R21: 20 | S21: =PROPER(CustomerSupport[[#This Row],[Resolution]]) -> Wish Mouth Build Resource Though. | T21: =TRIM(CustomerSupport[[#This Row],[Customer Name]]) -> Jeffrey Robertson | U21: =MONTH(CustomerSupport[[#This Row],[Date of Purchase]]) -> 3 | V21: =TEXT('Working data'!G21,"mmmm") -> March | W21: =YEAR(CustomerSupport[[#This Row],[Date of Purchase]]) -> 2021 | X21: =IF(OR(O21="",P21=""),"",(P21-O21)*24) -> 19.716667
A22: 21 | B22: Suzanne Holmes | C22: rogermcgrath@example.net | D22: 28 | E22: Other | F22: HP Pavilion | G22: 44347 | H22: Refund request | I22: Payment issue | J22: I'm having an issue with the {product_purchased}. Please assist. " -name "Microsoft Surface Pro. " " -version 1.10.2 "1.10.2" " -usage I've checked for any available software updates for my {product_purchased}, but there are none. | K22: Pending Customer Response | M22: High | N22: Chat | O22: 45078.214 | R22: 21 | S22: =PROPER(CustomerSupport[[#This Row],[Resolution]]) | T22: =TRIM(CustomerSupport[[#This Row],[Customer Name]]) -> Suzanne Holmes | U22: =MONTH(CustomerSupport[[#This Row],[Date of Purchase]]) -> 5 | V22: =TEXT('Working data'!G22,"mmmm") -> May | W22: =YEAR(CustomerSupport[[#This Row],[Date of Purchase]]) -> 2021 | X22: =IF(OR(O22="",P22=""),"",(P22-O22)*24)
A23: 22 | B23: Tanner Conley | C23: zbond@example.net | D23: 66 | E23: Male | F23: Fitbit Versa Smartwatch | G23: 43865 | H23: Cancellation request | I23: Installation support | J23: I'm having an issue with the {product_purchased}. Please assist. The email address should change to: customer@julietr.com, as there is a unique id number unique for each product. You I've tried different settings and configurations on my {product_purchased}, but the issue persists. | K23: Pending Customer Response | M23: Critical | N23: Social media | O23: 45077.998 | R23: 22 | S23: =PROPER(CustomerSupport[[#This Row],[Resolution]]) | T23: =TRIM(CustomerSupport[[#This Row],[Customer Name]]) -> Tanner Conley | U23: =MONTH(CustomerSupport[[#This Row],[Date of Purchase]]) -> 2 | V23: =TEXT('Working data'!G23,"mmmm") -> February | W23: =YEAR(CustomerSupport[[#This Row],[Date of Purchase]]) -> 2020 | X23: =IF(OR(O23="",P23=""),"",(P23-O23)*24)
A24: 23 | B24: Stephanie Nelson DVM | C24: ljohnson@example.org | D24: 54 | E24: Female | F24: Xbox | G24: 43872 | H24: Cancellation request | I24: Delivery problem | J24: I'm having an issue with the {product_purchased}. Please assist. (And if need be this time, that could help.) 1.3.2.1 Update my version to 3.0 or more. The issue I'm facing is intermittent. Sometimes it works fine, but other times it acts up unexpectedly. | K24: Open | M24: Medium | N24: Social media | R24: 23 | S24: =PROPER(CustomerSupport[[#This Row],[Resolution]]) | T24: =TRIM(CustomerSupport[[#This Row],[Customer Name]]) -> Stephanie Nelson DVM | U24: =MONTH(CustomerSupport[[#This Row],[Date of Purchase]]) -> 2 | V24: =TEXT('Working data'!G24,"mmmm") -> February | W24: =YEAR(CustomerSupport[[#This Row],[Date of Purchase]]) -> 2020 | X24: =IF(OR(O24="",P24=""),"",(P24-O24)*24)
A25: 24 | B25: Antonio Scott | C25: carlsonmatthew@example.org | D25: 63 | E25: Female | F25: Nintendo Switch Pro Controller | G25: 44414 | H25: Technical issue | I25: Refund request | J25: I'm having an issue with the {product_purchased}. Please assist. I'll take care of those. I've performed a factory reset on my {product_purchased}, hoping it would resolve the problem, but it didn't help. | K25: Pending Customer Response | M25: Low | N25: Social media | O25: 45078.379 | R25: 24 | S25: =PROPER(CustomerSupport[[#This Row],[Resolution]]) | T25: =TRIM(CustomerSupport[[#This Row],[Customer Name]]) -> Antonio Scott | U25: =MONTH(CustomerSupport[[#This Row],[Date of Purchase]]) -> 8 | V25: =TEXT('Working data'!G25,"mmmm") -> August | W25: =YEAR(CustomerSupport[[#This Row],[Date of Purchase]]) -> 2021 | X25: =IF(OR(O25="",P25=""),"",(P25-O25)*24)
A26: 25 | B26: John Cuevas | C26: lbarron@example.org | D26: 19 | E26: Male | F26: Amazon Kindle | G26: 44341 | H26: Product inquiry | I26: Display issue | J26: I'm having an issue with the {product_purchased}. Please assist. {product_purchased} does not represent the price which you received by the day immediately before the shipment date. In many cases, this is the I've noticed a sudden decrease in battery life on my {product_purchased}. It used to last much longer. | K26: Open | M26: Critical | N26: Email | R26: 25 | S26: =PROPER(CustomerSupport[[#This Row],[Resolution]]) | T26: =TRIM(CustomerSupport[[#This Row],[Customer Name]]) -> John Cuevas | U26: =MONTH(CustomerSupport[[#This Row],[Date of Purchase]]) -> 5 | V26: =TEXT('Working data'!G26,"mmmm") -> May | W26: =YEAR(CustomerSupport[[#This Row],[Date of Purchase]]) -> 2021 | X26: =IF(OR(O26="",P26=""),"",(P26-O26)*24)
A27: 26 | B27: Gregory Bautista | C27: johnstonbeth@example.com | D27: 35 | E27: Other | F27: HP Pavilion | G27: 44382 | H27: Product inquiry | I27: Refund request | J27: My {product_purchased} is making strange noises and not functioning properly. I suspect there might be a hardware issue. Can you please help me with this? Thank you, Thank you for posting. It took me a I'm experiencing this issue on multiple devices of the same model, so it seems to be a widespread problem. | K27: Pending Customer Response | M27: Medium | N27: Social media | O27: 45078.793 | R27: 26 | S27: =PROPER(CustomerSupport[[#This Row],[Resolution]]) | T27: =TRIM(CustomerSupport[[#This Row],[Customer Name]]) -> Gregory Bautista | U27: =MONTH(CustomerSupport[[#This Row],[Date of Purchase]]) -> 7 | V27: =TEXT('Working data'!G27,"mmmm") -> July | W27: =YEAR(CustomerSupport[[#This Row],[Date of Purchase]]) -> 2021 | X27: =IF(OR(O27="",P27=""),"",(P27-O27)*24)
A28: 27 | B28: Ryan Sharp | C28: pmercado@example.org | D28: 22 | E28: Other | F28: Lenovo ThinkPad | G28: 43953 | H28: Billing inquiry | I28: Cancellation request | J28: I'm encountering a software bug in the {product_purchased}. Whenever I try to perform a specific action, the application crashes. Are there any updates or fixes available? On Windows Vista, this is not possible. If you are I've performed a factory reset on my {product_purchased}, hoping it would resolve the problem, but it didn't help. | K28: Pending Customer Response | M28: Low | N28: Social media | O28: 45078.835 | R28: 27 | S28: =PROPER(CustomerSupport[[#This Row],[Resolution]]) | T28: =TRIM(CustomerSupport[[#This Row],[Customer Name]]) -> Ryan Sharp | U28: =MONTH(CustomerSupport[[#This Row],[Date of Purchase]]) -> 5 | V28: =TEXT('Working data'!G28,"mmmm") -> May | W28: =YEAR(CustomerSupport[[#This Row],[Date of Purchase]]) -> 2020 | X28: =IF(OR(O28="",P28=""),"",(P28-O28)*24)
A29: 28 | B29: Michael Mcdowell | C29: jeffersonmichael@example.net | D29: 21 | E29: Other | F29: Fitbit Charge | G29: 44116 | H29: Cancellation request | I29: Product setup | J29: I'm having an issue with the {product_purchased}. Please assist. {{product_purchased}} must be a valid email address for your order and are valid for one week in advance. Please make your purchases as quickly as possible The issue I'm facing is intermittent. Sometimes it works fine, but other times it acts up unexpectedly. | K29: Open | M29: High | N29: Phone | R29: 28 | S29: =PROPER(CustomerSupport[[#This Row],[Resolution]]) | T29: =TRIM(CustomerSupport[[#This Row],[Customer Name]]) -> Michael Mcdowell | U29: =MONTH(CustomerSupport[[#This Row],[Date of Purchase]]) -> 10 | V29: =TEXT('Working data'!G29,"mmmm") -> October | W29: =YEAR(CustomerSupport[[#This Row],[Date of Purchase]]) -> 2020 | X29: =IF(OR(O29="",P29=""),"",(P29-O29)*24)
A30: 29 | B30: Christine Wang | C30: garciastacy@example.com | D30: 30 | E30: Other | F30: Fitbit Charge | G30: 43992 | H30: Technical issue | I30: Product recommendation | J30: I'm having an issue with the {product_purchased}. Please assist. Thank you." A statement from the consumer group had been released by Microsoft late on Tuesday afternoon. "The purchase of this product was made using a contract with I'm using the original charger that came with my {product_purchased}, but it's not charging properly. | K30: Closed | L30: Soldier we such inside. | M30: Critical | N30: Phone | O30: 45077.97 | P30: 45078.252 | Q30: 5 | R30: 29 | S30: =PROPER(CustomerSupport[[#This Row],[Resolution]]) -> Soldier We Such Inside. | T30: =TRIM(CustomerSupport[[#This Row],[Customer Name]]) -> Christine Wang | U30: =MONTH(CustomerSupport[[#This Row],[Date of Purchase]]) -> 6 | V30: =TEXT('Working data'!G30,"mmmm") -> June | W30: =YEAR(CustomerSupport[[#This Row],[Date of Purchase]]) -> 2020 | X30: =IF(OR(O30="",P30=""),"",(P30-O30)*24) -> 6.7666667
A31: 30 | B31: Austin George | C31: shericase@example.net | D31: 67 | E31: Male | F31: Xbox | G31: 44191 | H31: Cancellation request | I31: Cancellation request | J31: I'm having an issue with the {product_purchased}. Please assist. It's not possible to remove the missing content. I've already contacted customer support multiple times, but the issue remains unresolved. | K31: Closed | L31: Firm sort voice above which site arrive. | M31: Medium | N31: Phone | O31: 45078.038 | P31: 45078.766 | Q31: 1 | R31: 30 | S31: =PROPER(CustomerSupport[[#This Row],[Resolution]]) -> Firm Sort Voice Above Which Site Arrive. | T31: =TRIM(CustomerSupport[[#This Row],[Customer Name]]) -> Austin George | U31: =MONTH(CustomerSupport[[#This Row],[Date of Purchase]]) -> 12 | V31: =TEXT('Working data'!G31,"mmmm") -> December | W31: =YEAR(CustomerSupport[[#This Row],[Date of Purchase]]) -> 2020 | X31: =IF(OR(O31="",P31=""),"",(P31-O31)*24) -> 17.483333
A32: 31 | B32: Wendy Roberts | C32: jessicahenderson@example.net | D32: 22 | E32: Other | F32: Adobe Photoshop | G32: 44224 | H32: Billing inquiry | I32: Product setup | J32: I'm having an issue with the {product_purchased}. Please assist. I'm using a brand new product. What a strange situation. I've just purchased a brand new one. What to do? I've noticed that the issue occurs consistently when I use a specific feature or application on my {product_purchased}. | K32: Open | M32: Low | N32: Email | R32: 31 | S32: =PROPER(CustomerSupport[[#This Row],[Resolution]]) | T32: =TRIM(CustomerSupport[[#This Row],[Customer Name]]) -> Wendy Roberts | U32: =MONTH(CustomerSupport[[#This Row],[Date of Purchase]]) -> 1 | V32: =TEXT('Working data'!G32,"mmmm") -> January | W32: =YEAR(CustomerSupport[[#This Row],[Date of Purchase]]) -> 2021 | X32: =IF(OR(O32="",P32=""),"",(P32-O32)*24)
A33: 32 | B33: Robert Wilson | C33: zstewart@example.org | D33: 60 | E33: Male | F33: GoPro Action Camera | G33: 44550 | H33: Technical issue | I33: Product compatibility | J33: I'm having an issue with the {product_purchased}. Please assist. The seller has sold the item for $29.89. When we receive your replacement, we will exchange the item for a full refund or exchange immediately upon I've already contacted customer support multiple times, but the issue remains unresolved. | K33: Closed | L33: Certain myself month past tree benefit. | M33: Medium | N33: Social media | O33: 45078.279 | P33: 45078.303 | Q33: 3 | R33: 32 | S33: =PROPER(CustomerSupport[[#This Row],[Resolution]]) -> Certain Myself Month Past Tree Benefit. | T33: =TRIM(CustomerSupport[[#This Row],[Customer Name]]) -> Robert Wilson | U33: =MONTH(CustomerSupport[[#This Row],[Date of Purchase]]) -> 12 | V33: =TEXT('Working data'!G33,"mmmm") -> December | W33: =YEAR(CustomerSupport[[#This Row],[Date of Purchase]]) -> 2021 | X33: =IF(OR(O33="",P33=""),"",(P33-O33)*24) -> 0.56666667
A34: 33 | B34: Christina Gray | C34: greenkeith@example.net | D34: 36 | E34: Female | F34: Fitbit Charge | G34: 44537 | H34: Billing inquiry | I34: Product recommendation | J34: I've noticed a software bug in the {product_purchased} app. It's causing data loss and unexpected errors. How can I resolve this issue? I need assistance as soon as possible because it's affecting my work and productivity. | K34: Pending Customer Response | M34: Medium | N34: Chat | O34: 45078.817 | R34: 33 | S34: =PROPER(CustomerSupport[[#This Row],[Resolution]]) | T34: =TRIM(CustomerSupport[[#This Row],[Customer Name]]) -> Christina Gray | U34: =MONTH(CustomerSupport[[#This Row],[Date of Purchase]]) -> 12 | V34: =TEXT('Working data'!G34,"mmmm") -> December | W34: =YEAR(CustomerSupport[[#This Row],[Date of Purchase]]) -> 2021 | X34: =IF(OR(O34="",P34=""),"",(P34-O34)*24)
A35: 34 | B35: Timothy Lyons | C35: darlenelee@example.org | D35: 50 | E35: Male | F35: Autodesk AutoCAD | G35: 44539 | H35: Refund request | I35: Hardware issue | J35: I'm having an issue with the {product_purchased}. Please assist. We hope that every vendor takes the time it takes in to do the following: "Remove the product from your account - notify consumers, call them, make their I'm concerned about the security of my {product_purchased} and would like to ensure that my data is safe. | K35: Closed | L35: However financial development significant camera job every. | M35: Critical | N35: Social media | O35: 45078.084 | P35: 45078.768 | Q35: 5 | R35: 34 | S35: =PROPER(CustomerSupport[[#This Row],[Resolution]]) -> However Financial Development Significant Camera Job Every. | T35: =TRIM(CustomerSupport[[#This Row],[Customer Name]]) -> Timothy Lyons | U35: =MONTH(CustomerSupport[[#This Row],[Date of Purchase]]) -> 12 | V35: =TEXT('Working data'!G35,"mmmm") -> December | W35: =YEAR(CustomerSupport[[#This Row],[Date of Purchase]]) -> 2021 | X35: =IF(OR(O35="",P35=""),"",(P35-O35)*24) -> 16.4
A36: 35 | B36: Stacy Jones | C36: fernandezmark@example.org | D36: 27 | E36: Male | F36: Microsoft Xbox Controller | G36: 44295 | H36: Refund request | I36: Installation support | J36: I'm having an issue with the {product_purchased}. Please assist. 3-3 We are in, the first day, at the {product_purchased}. Please assist. 3-2 Please assist us I've recently updated the firmware of my {product_purchased}, and the issue started happening afterward. Could it be related to the update? | K36: Pending Customer Response | M36: Low | N36: Chat | O36: 45078.868 | R36: 35 | S36: =PROPER(CustomerSupport[[#This Row],[Resolution]]) | T36: =TRIM(CustomerSupport[[#This Row],[Customer Name]]) -> Stacy Jones | U36: =MONTH(CustomerSupport[[#This Row],[Date of Purchase]]) -> 4 | V36: =TEXT('Working data'!G36,"mmmm") -> April | W36: =YEAR(CustomerSupport[[#This Row],[Date of Purchase]]) -> 2021 | X36: =IF(OR(O36="",P36=""),"",(P36-O36)*24)
A37: 36 | B37: Joann King | C37: jessica10@example.org | D37: 24 | E37: Other | F37: GoPro Hero | G37: 44117 | H37: Cancellation request | I37: Product recommendation | J37: I've recently set up my {product_purchased}, but it fails to connect to any available networks. What steps should I take to troubleshoot this issue? If you know the answer, please let me know. Do I I've noticed a sudden decrease in battery life on my {product_purchased}. It used to last much longer. | K37: Closed | L37: Reach paper ability effort learn. | M37: High | N37: Chat | O37: 45078.331 | P37: 45078.01 | Q37: 1 | R37: 36 | S37: =PROPER(CustomerSupport[[#This Row],[Resolution]]) -> Reach Paper Ability Effort Learn. | T37: =TRIM(CustomerSupport[[#This Row],[Customer Name]]) -> Joann King | U37: =MONTH(CustomerSupport[[#This Row],[Date of Purchase]]) -> 10 | V37: =TEXT('Working data'!G37,"mmmm") -> October | W37: =YEAR(CustomerSupport[[#This Row],[Date of Purchase]]) -> 2020 | X37: =IF(OR(O37="",P37=""),"",(P37-O37)*24) -> -7.7
A38: 37 | B38: Ruben Henry | C38: katherinehoward@example.net | D38: 65 | E38: Female | F38: Canon EOS | G38: 43904 | H38: Refund request | I38: Hardware issue | J38: I'm having an issue with the {product_purchased}. Please assist. I have to ask for support from you, the customers, before the item's arrival and I can't do that. In the short term, will you pay me I've followed the troubleshooting steps mentioned in the user manual, but the issue persists. | K38: Pending Customer Response | M38: Medium | N38: Email | O38: 45078.661 | R38: 37 | S38: =PROPER(CustomerSupport[[#This Row],[Resolution]]) | T38: =TRIM(CustomerSupport[[#This Row],[Customer Name]]) -> Ruben Henry | U38: =MONTH(CustomerSupport[[#This Row],[Date of Purchase]]) -> 3 | V38: =TEXT('Working data'!G38,"mmmm") -> March | W38: =YEAR(CustomerSupport[[#This Row],[Date of Purchase]]) -> 2020 | X38: =IF(OR(O38="",P38=""),"",(P38-O38)*24)
A39: 38 | B39: Morgan Wagner | C39: elizabethlamb@example.com | D39: 39 | E39: Female | F39: Amazon Kindle | G39: 44076 | H39: Product inquiry | I39: Product compatibility | J39: I've forgotten my password for my {product_purchased} account, and the password reset option is not working. How can I recover my account? I can reset my password by entering the following: My password still valid: password is expired I've recently updated the firmware of my {product_purchased}, and the issue started happening afterward. Could it be related to the update? | K39: Open | M39: Medium | N39: Chat | R39: 38 | S39: =PROPER(CustomerSupport[[#This Row],[Resolution]]) | T39: =TRIM(CustomerSupport[[#This Row],[Customer Name]]) -> Morgan Wagner | U39: =MONTH(CustomerSupport[[#This Row],[Date of Purchase]]) -> 9 | V39: =TEXT('Working data'!G39,"mmmm") -> September | W39: =YEAR(CustomerSupport[[#This Row],[Date of Purchase]]) -> 2020 | X39: =IF(OR(O39="",P39=""),"",(P39-O39)*24)
A40: 39 | B40: Kevin Ingram | C40: victor62@example.net | D40: 19 | E40: Male | F40: Google Pixel | G40: 44449 | H40: Technical issue | I40: Account access | J40: I'm having an issue with the {product_purchased}. Please assist. 1. Do I need to purchase a refund? There is a way to purchase a refund from ZEROHITS, but there's not a I'm unable to find the option to perform the desired action in the {product_purchased}. Could you please guide me through the steps? | K40: Closed | L40: North second between this cell opportunity movement. | M40: Critical | N40: Phone | O40: 45078.782 | P40: 45077.912 | Q40: 3 | R40: 39 | S40: =PROPER(CustomerSupport[[#This Row],[Resolution]]) -> North Second Between This Cell Opportunity Movement. | T40: =TRIM(CustomerSupport[[#This Row],[Customer Name]]) -> Kevin Ingram | U40: =MONTH(CustomerSupport[[#This Row],[Date of Purchase]]) -> 9 | V40: =TEXT('Working data'!G40,"mmmm") -> September | W40: =YEAR(CustomerSupport[[#This Row],[Date of Purchase]]) -> 2021 | X40: =IF(OR(O40="",P40=""),"",(P40-O40)*24) -> -20.866667
...

Sheet Audit check
A2: Duplicate Ticket IDs found | B2: No
A3: Total CSAT blanks | B3: =COUNTBLANK('Working data'!Q2:Q8470) -> 5700
A4: Total CSAT filled | B4: =COUNTA('Working data'!Q2:Q8470) -> 2769
A5: Blank percentage | B5: =B3/(B3+B4)*100/100 -> 0.67304286
A6: Trim Applied | B6: Yes
H28: x

Sheet KPI_Summary
A2: Total Tickets | B2: =COUNTA(CustomerSupport[Ticket ID]) -> 8469
A3: Open Tickets | B3: =COUNTIF('Working data'!K:K,"Open") -> 2819
A4: Closed Tickets | B4: =COUNTIF('Working data'!K:K,"Closed") -> 2769
A5: Pending Tickets | B5: =COUNTIF('Working data'!K:K,"Pending Customer Response") -> 2881
A6: Avg CSAT Score | B6: =AVERAGE('Working data'!Q2:Q8470) -> 2.9913326

Sheet Analysis Sheet
A3: Row Labels | B3: Count of Ticket ID
A4: Closed | B4: 1366
A5: Open | B5: 1433
A6: Pending Customer Response | B6: 1434
A7: Grand Total | B7: 4233
A15: Row Labels | B15: Count of Ticket ID
A16: Billing inquiry | B16: 832
A17: Cancellation request | B17: 845
A18: Product inquiry | B18: 794
A19: Refund request | B19: 854
A20: Technical issue | B20: 908
A21: Grand Total | B21: 4233

Sheet Dashboard
A1: Customer Support Ticket Dashboard
A6: Total Tickets | D6: Open Tickets | G6: Closed Tickets | J6: Pending Tickets | M6: Avg CSAT Score
A8: =KPI_Summary!B2 -> 8469 | D8: =KPI_Summary!B3 -> 2819 | G8: =KPI_Summary!B4 -> 2769 | J8: =KPI_Summary!B5 -> 2881 | M8: =KPI_Summary!B6 -> 2.9913326
