Workbook
Name Slicer_Country: #N/A
Name Slicer_TransactionType: #N/A
Name Slicer_Year_of_Transaction: #N/A

Sheet Dashboard
B1: Finance Operations Dashboard
B8: Total Outstanding | E8: Total Disputed Amount | H8: % Invoices Late | K8: Total Payable Balance | N8: Total Receivable Balance
B10: =SUMIFS(Raw_Data!F:F,Raw_Data!T:T,1) -> 668446.27 | E10: =SUMIFS(Raw_Data!F:F,Raw_Data!S:S,1) -> 36746.12 | H10: =AVERAGE(Raw_Data!R:R) -> 0.3356592 | K10: =SUMIFS(Raw_Data!F:F,Raw_Data!B:B,"Payable",Raw_Data!T:T,1) -> 668446.27 | N10: =SUMIFS(Raw_Data!F:F,Raw_Data!B:B,"Receivables",Raw_Data!T:T,1) -> 0

Sheet Raw_Data
A1: TransactionID | B1: TransactionType | C1: PartyName | D1: InvoiceDate | E1: DueDate | F1: Amount | G1: Currency | H1: PaymentStatus | I1: PaidDate | J1: DaysLate | K1: DisputedFlag | L1: Country | M1: PaperlessDate | N1: PaperlessBill | O1: Terms | P1: DatasetSource | Q1: AgingBucket | R1: Late Flag | S1: Disputed Flags | T1: Open | U1: Year of Transaction
A2: AP10000 | B2: Payable | C2: BluePrints | D2: 45642 | E2: 45672 | F2: 344.25 | G2: EUR | H2: Open | I2: 0 | L2: 391 | O2: Net 30 | P2: AP | Q2: =IF(Table4[[#This Row],[DaysLate]]="","NA",IF(Table4[[#This Row],[DaysLate]]<=0,"On Time",IF(Table4[[#This Row],[DaysLate]]<=30,"1-30 Days",IF(Table4[[#This Row],[DaysLate]]<=60,"30-60 Days",IF(Table4[[#This Row],[DaysLate]]<=90,"60-90 Days","90+ Days"))))) -> NA | R2: =IF(Table4[[#This Row],[DaysLate]]="","",IF(Table4[[#This Row],[DaysLate]]>0,1,0)) | S2: =IF(Table4[[#This Row],[DisputedFlag]]="","",IF(Table4[[#This Row],[DisputedFlag]]="Yes",1,0)) | T2: =IF(Table4[[#This Row],[PaymentStatus]]="Open",1,0) -> 1 | U2: =IF(Table4[[#This Row],[InvoiceDate]]<>"",YEAR(Table4[[#This Row],[InvoiceDate]]),"") -> 2024
A3: AP10001 | B3: Payable | C3: BluePrints | D3: 45430 | E3: 45460 | F3: 3298.38 | G3: CAD | H3: Partial | I3: 0 | L3: 406 | O3: Net 30 | P3: AP | Q3: =IF(Table4[[#This Row],[DaysLate]]="","NA",IF(Table4[[#This Row],[DaysLate]]<=0,"On Time",IF(Table4[[#This Row],[DaysLate]]<=30,"1-30 Days",IF(Table4[[#This Row],[DaysLate]]<=60,"30-60 Days",IF(Table4[[#This Row],[DaysLate]]<=90,"60-90 Days","90+ Days"))))) -> NA | R3: =IF(Table4[[#This Row],[DaysLate]]="","",IF(Table4[[#This Row],[DaysLate]]>0,1,0)) | S3: =IF(Table4[[#This Row],[DisputedFlag]]="","",IF(Table4[[#This Row],[DisputedFlag]]="Yes",1,0)) | T3: =IF(Table4[[#This Row],[PaymentStatus]]="Open",1,0) -> 0 | U3: =IF(Table4[[#This Row],[InvoiceDate]]<>"",YEAR(Table4[[#This Row],[InvoiceDate]]),"") -> 2024
A4: AP10002 | B4: Payable | C4: Fast Travel | D4: 45347 | E4: 45377 | F4: 1023.43 | G4: GBP | H4: Open | I4: 0 | L4: 770 | O4: Net 30 | P4: AP | Q4: =IF(Table4[[#This Row],[DaysLate]]="","NA",IF(Table4[[#This Row],[DaysLate]]<=0,"On Time",IF(Table4[[#This Row],[DaysLate]]<=30,"1-30 Days",IF(Table4[[#This Row],[DaysLate]]<=60,"30-60 Days",IF(Table4[[#This Row],[DaysLate]]<=90,"60-90 Days","90+ Days"))))) -> NA | R4: =IF(Table4[[#This Row],[DaysLate]]="","",IF(Table4[[#This Row],[DaysLate]]>0,1,0)) | S4: =IF(Table4[[#This Row],[DisputedFlag]]="","",IF(Table4[[#This Row],[DisputedFlag]]="Yes",1,0)) | T4: =IF(Table4[[#This Row],[PaymentStatus]]="Open",1,0) -> 1 | U4: =IF(Table4[[#This Row],[InvoiceDate]]<>"",YEAR(Table4[[#This Row],[InvoiceDate]]),"") -> 2024
A5: AP10003 | B5: Payable | C5: ABC Supplies | D5: 45299 | E5: 45329 | F5: 4433.05 | G5: USD | H5: Partial | I5: 0 | L5: 818 | O5: Net 30 | P5: AP | Q5: =IF(Table4[[#This Row],[DaysLate]]="","NA",IF(Table4[[#This Row],[DaysLate]]<=0,"On Time",IF(Table4[[#This Row],[DaysLate]]<=30,"1-30 Days",IF(Table4[[#This Row],[DaysLate]]<=60,"30-60 Days",IF(Table4[[#This Row],[DaysLate]]<=90,"60-90 Days","90+ Days"))))) -> NA | R5: =IF(Table4[[#This Row],[DaysLate]]="","",IF(Table4[[#This Row],[DaysLate]]>0,1,0)) | S5: =IF(Table4[[#This Row],[DisputedFlag]]="","",IF(Table4[[#This Row],[DisputedFlag]]="Yes",1,0)) | T5: =IF(Table4[[#This Row],[PaymentStatus]]="Open",1,0) -> 0 | U5: =IF(Table4[[#This Row],[InvoiceDate]]<>"",YEAR(Table4[[#This Row],[InvoiceDate]]),"") -> 2024
A6: AP10004 | B6: Payable | C6: ABC Supplies | D6: 45435 | E6: 45465 | F6: 4345.14 | G6: GBP | H6: Partial | I6: 0 | L6: 897 | O6: Net 30 | P6: AP | Q6: =IF(Table4[[#This Row],[DaysLate]]="","NA",IF(Table4[[#This Row],[DaysLate]]<=0,"On Time",IF(Table4[[#This Row],[DaysLate]]<=30,"1-30 Days",IF(Table4[[#This Row],[DaysLate]]<=60,"30-60 Days",IF(Table4[[#This Row],[DaysLate]]<=90,"60-90 Days","90+ Days"))))) -> NA | R6: =IF(Table4[[#This Row],[DaysLate]]="","",IF(Table4[[#This Row],[DaysLate]]>0,1,0)) | S6: =IF(Table4[[#This Row],[DisputedFlag]]="","",IF(Table4[[#This Row],[DisputedFlag]]="Yes",1,0)) | T6: =IF(Table4[[#This Row],[PaymentStatus]]="Open",1,0) -> 0 | U6: =IF(Table4[[#This Row],[InvoiceDate]]<>"",YEAR(Table4[[#This Row],[InvoiceDate]]),"") -> 2024
A7: AP10005 | B7: Payable | C7: Fast Travel | D7: 45482 | E7: 45512 | F7: 1599.18 | G7: AUD | H7: Open | I7: 0 | L7: 770 | O7: Net 30 | P7: AP | Q7: =IF(Table4[[#This Row],[DaysLate]]="","NA",IF(Table4[[#This Row],[DaysLate]]<=0,"On Time",IF(Table4[[#This Row],[DaysLate]]<=30,"1-30 Days",IF(Table4[[#This Row],[DaysLate]]<=60,"30-60 Days",IF(Table4[[#This Row],[DaysLate]]<=90,"60-90 Days","90+ Days"))))) -> NA | R7: =IF(Table4[[#This Row],[DaysLate]]="","",IF(Table4[[#This Row],[DaysLate]]>0,1,0)) | S7: =IF(Table4[[#This Row],[DisputedFlag]]="","",IF(Table4[[#This Row],[DisputedFlag]]="Yes",1,0)) | T7: =IF(Table4[[#This Row],[PaymentStatus]]="Open",1,0) -> 1 | U7: =IF(Table4[[#This Row],[InvoiceDate]]<>"",YEAR(Table4[[#This Row],[InvoiceDate]]),"") -> 2024
A8: AP10006 | B8: Payable | C8: BluePrints | D8: 45646 | E8: 45676 | F8: 894.13 | G8: USD | H8: Open | I8: 0 | L8: 391 | O8: Net 30 | P8: AP | Q8: =IF(Table4[[#This Row],[DaysLate]]="","NA",IF(Table4[[#This Row],[DaysLate]]<=0,"On Time",IF(Table4[[#This Row],[DaysLate]]<=30,"1-30 Days",IF(Table4[[#This Row],[DaysLate]]<=60,"30-60 Days",IF(Table4[[#This Row],[DaysLate]]<=90,"60-90 Days","90+ Days"))))) -> NA | R8: =IF(Table4[[#This Row],[DaysLate]]="","",IF(Table4[[#This Row],[DaysLate]]>0,1,0)) | S8: =IF(Table4[[#This Row],[DisputedFlag]]="","",IF(Table4[[#This Row],[DisputedFlag]]="Yes",1,0)) | T8: =IF(Table4[[#This Row],[PaymentStatus]]="Open",1,0) -> 1 | U8: =IF(Table4[[#This Row],[InvoiceDate]]<>"",YEAR(Table4[[#This Row],[InvoiceDate]]),"") -> 2024
A9: AP10007 | B9: Payable | C9: Fast Travel | D9: 45560 | E9: 45590 | F9: 1303.06 | G9: GBP | H9: Paid | I9: 45593 | J9: 3 | L9: 818 | O9: Net 30 | P9: AP | Q9: =IF(Table4[[#This Row],[DaysLate]]="","NA",IF(Table4[[#This Row],[DaysLate]]<=0,"On Time",IF(Table4[[#This Row],[DaysLate]]<=30,"1-30 Days",IF(Table4[[#This Row],[DaysLate]]<=60,"30-60 Days",IF(Table4[[#This Row],[DaysLate]]<=90,"60-90 Days","90+ Days"))))) -> 1-30 Days | R9: =IF(Table4[[#This Row],[DaysLate]]="","",IF(Table4[[#This Row],[DaysLate]]>0,1,0)) -> 1 | S9: =IF(Table4[[#This Row],[DisputedFlag]]="","",IF(Table4[[#This Row],[DisputedFlag]]="Yes",1,0)) | T9: =IF(Table4[[#This Row],[PaymentStatus]]="Open",1,0) -> 0 | U9: =IF(Table4[[#This Row],[InvoiceDate]]<>"",YEAR(Table4[[#This Row],[InvoiceDate]]),"") -> 2024
A10: AP10008 | B10: Payable | C10: ABC Supplies | D10: 45334 | E10: 45364 | F10: 3481.8 | G10: CAD | H10: Paid | I10: 45367 | J10: 3 | L10: 406 | O10: Net 30 | P10: AP | Q10: =IF(Table4[[#This Row],[DaysLate]]="","NA",IF(Table4[[#This Row],[DaysLate]]<=0,"On Time",IF(Table4[[#This Row],[DaysLate]]<=30,"1-30 Days",IF(Table4[[#This Row],[DaysLate]]<=60,"30-60 Days",IF(Table4[[#This Row],[DaysLate]]<=90,"60-90 Days","90+ Days"))))) -> 1-30 Days | R10: =IF(Table4[[#This Row],[DaysLate]]="","",IF(Table4[[#This Row],[DaysLate]]>0,1,0)) -> 1 | S10: =IF(Table4[[#This Row],[DisputedFlag]]="","",IF(Table4[[#This Row],[DisputedFlag]]="Yes",1,0)) | T10: =IF(Table4[[#This Row],[PaymentStatus]]="Open",1,0) -> 0 | U10: =IF(Table4[[#This Row],[InvoiceDate]]<>"",YEAR(Table4[[#This Row],[InvoiceDate]]),"") -> 2024
A11: AP10009 | B11: Payable | C11: ABC Supplies | D11: 45470 | E11: 45500 | F11: 217.97 | G11: USD | H11: Open | I11: 0 | L11: 897 | O11: Net 30 | P11: AP | Q11: =IF(Table4[[#This Row],[DaysLate]]="","NA",IF(Table4[[#This Row],[DaysLate]]<=0,"On Time",IF(Table4[[#This Row],[DaysLate]]<=30,"1-30 Days",IF(Table4[[#This Row],[DaysLate]]<=60,"30-60 Days",IF(Table4[[#This Row],[DaysLate]]<=90,"60-90 Days","90+ Days"))))) -> NA | R11: =IF(Table4[[#This Row],[DaysLate]]="","",IF(Table4[[#This Row],[DaysLate]]>0,1,0)) | S11: =IF(Table4[[#This Row],[DisputedFlag]]="","",IF(Table4[[#This Row],[DisputedFlag]]="Yes",1,0)) | T11: =IF(Table4[[#This Row],[PaymentStatus]]="Open",1,0) -> 1 | U11: =IF(Table4[[#This Row],[InvoiceDate]]<>"",YEAR(Table4[[#This Row],[InvoiceDate]]),"") -> 2024
A12: AP10010 | B12: Payable | C12: BluePrints | D12: 45360 | E12: 45390 | F12: 1809.07 | G12: EUR | H12: Partial | I12: 0 | L12: 406 | O12: Net 30 | P12: AP | Q12: =IF(Table4[[#This Row],[DaysLate]]="","NA",IF(Table4[[#This Row],[DaysLate]]<=0,"On Time",IF(Table4[[#This Row],[DaysLate]]<=30,"1-30 Days",IF(Table4[[#This Row],[DaysLate]]<=60,"30-60 Days",IF(Table4[[#This Row],[DaysLate]]<=90,"60-90 Days","90+ Days"))))) -> NA | R12: =IF(Table4[[#This Row],[DaysLate]]="","",IF(Table4[[#This Row],[DaysLate]]>0,1,0)) | S12: =IF(Table4[[#This Row],[DisputedFlag]]="","",IF(Table4[[#This Row],[DisputedFlag]]="Yes",1,0)) | T12: =IF(Table4[[#This Row],[PaymentStatus]]="Open",1,0) -> 0 | U12: =IF(Table4[[#This Row],[InvoiceDate]]<>"",YEAR(Table4[[#This Row],[InvoiceDate]]),"") -> 2024
A13: AP10011 | B13: Payable | C13: BluePrints | D13: 45575 | E13: 45605 | F13: 884.1 | G13: USD | H13: Open | I13: 0 | L13: 770 | O13: Net 30 | P13: AP | Q13: =IF(Table4[[#This Row],[DaysLate]]="","NA",IF(Table4[[#This Row],[DaysLate]]<=0,"On Time",IF(Table4[[#This Row],[DaysLate]]<=30,"1-30 Days",IF(Table4[[#This Row],[DaysLate]]<=60,"30-60 Days",IF(Table4[[#This Row],[DaysLate]]<=90,"60-90 Days","90+ Days"))))) -> NA | R13: =IF(Table4[[#This Row],[DaysLate]]="","",IF(Table4[[#This Row],[DaysLate]]>0,1,0)) | S13: =IF(Table4[[#This Row],[DisputedFlag]]="","",IF(Table4[[#This Row],[DisputedFlag]]="Yes",1,0)) | T13: =IF(Table4[[#This Row],[PaymentStatus]]="Open",1,0) -> 1 | U13: =IF(Table4[[#This Row],[InvoiceDate]]<>"",YEAR(Table4[[#This Row],[InvoiceDate]]),"") -> 2024
A14: AP10012 | B14: Payable | C14: ABC Supplies | D14: 45065 | E14: 45095 | F14: 1491.7 | G14: GBP | H14: Open | I14: 0 | L14: 391 | O14: Net 30 | P14: AP | Q14: =IF(Table4[[#This Row],[DaysLate]]="","NA",IF(Table4[[#This Row],[DaysLate]]<=0,"On Time",IF(Table4[[#This Row],[DaysLate]]<=30,"1-30 Days",IF(Table4[[#This Row],[DaysLate]]<=60,"30-60 Days",IF(Table4[[#This Row],[DaysLate]]<=90,"60-90 Days","90+ Days"))))) -> NA | R14: =IF(Table4[[#This Row],[DaysLate]]="","",IF(Table4[[#This Row],[DaysLate]]>0,1,0)) | S14: =IF(Table4[[#This Row],[DisputedFlag]]="","",IF(Table4[[#This Row],[DisputedFlag]]="Yes",1,0)) | T14: =IF(Table4[[#This Row],[PaymentStatus]]="Open",1,0) -> 1 | U14: =IF(Table4[[#This Row],[InvoiceDate]]<>"",YEAR(Table4[[#This Row],[InvoiceDate]]),"") -> 2023
A15: AP10013 | B15: Payable | C15: ABC Supplies | D15: 45249 | E15: 45279 | F15: 4212.17 | G15: AUD | H15: Paid | I15: 45285 | J15: 6 | L15: 897 | O15: Net 30 | P15: AP | Q15: =IF(Table4[[#This Row],[DaysLate]]="","NA",IF(Table4[[#This Row],[DaysLate]]<=0,"On Time",IF(Table4[[#This Row],[DaysLate]]<=30,"1-30 Days",IF(Table4[[#This Row],[DaysLate]]<=60,"30-60 Days",IF(Table4[[#This Row],[DaysLate]]<=90,"60-90 Days","90+ Days"))))) -> 1-30 Days | R15: =IF(Table4[[#This Row],[DaysLate]]="","",IF(Table4[[#This Row],[DaysLate]]>0,1,0)) -> 1 | S15: =IF(Table4[[#This Row],[DisputedFlag]]="","",IF(Table4[[#This Row],[DisputedFlag]]="Yes",1,0)) | T15: =IF(Table4[[#This Row],[PaymentStatus]]="Open",1,0) -> 0 | U15: =IF(Table4[[#This Row],[InvoiceDate]]<>"",YEAR(Table4[[#This Row],[InvoiceDate]]),"") -> 2023
A16: AP10014 | B16: Payable | C16: BluePrints | D16: 45417 | E16: 45447 | F16: 1632.82 | G16: GBP | H16: Open | I16: 0 | L16: 818 | O16: Net 30 | P16: AP | Q16: =IF(Table4[[#This Row],[DaysLate]]="","NA",IF(Table4[[#This Row],[DaysLate]]<=0,"On Time",IF(Table4[[#This Row],[DaysLate]]<=30,"1-30 Days",IF(Table4[[#This Row],[DaysLate]]<=60,"30-60 Days",IF(Table4[[#This Row],[DaysLate]]<=90,"60-90 Days","90+ Days"))))) -> NA | R16: =IF(Table4[[#This Row],[DaysLate]]="","",IF(Table4[[#This Row],[DaysLate]]>0,1,0)) | S16: =IF(Table4[[#This Row],[DisputedFlag]]="","",IF(Table4[[#This Row],[DisputedFlag]]="Yes",1,0)) | T16: =IF(Table4[[#This Row],[PaymentStatus]]="Open",1,0) -> 1 | U16: =IF(Table4[[#This Row],[InvoiceDate]]<>"",YEAR(Table4[[#This Row],[InvoiceDate]]),"") -> 2024
A17: AP10015 | B17: Payable | C17: BluePrints | D17: 45081 | E17: 45111 | F17: 1887.67 | G17: EUR | H17: Paid | I17: 45111 | J17: 0 | L17: 770 | O17: Net 30 | P17: AP | Q17: =IF(Table4[[#This Row],[DaysLate]]="","NA",IF(Table4[[#This Row],[DaysLate]]<=0,"On Time",IF(Table4[[#This Row],[DaysLate]]<=30,"1-30 Days",IF(Table4[[#This Row],[DaysLate]]<=60,"30-60 Days",IF(Table4[[#This Row],[DaysLate]]<=90,"60-90 Days","90+ Days"))))) -> On Time | R17: =IF(Table4[[#This Row],[DaysLate]]="","",IF(Table4[[#This Row],[DaysLate]]>0,1,0)) -> 0 | S17: =IF(Table4[[#This Row],[DisputedFlag]]="","",IF(Table4[[#This Row],[DisputedFlag]]="Yes",1,0)) | T17: =IF(Table4[[#This Row],[PaymentStatus]]="Open",1,0) -> 0 | U17: =IF(Table4[[#This Row],[InvoiceDate]]<>"",YEAR(Table4[[#This Row],[InvoiceDate]]),"") -> 2023
A18: AP10016 | B18: Payable | C18: BluePrints | D18: 45270 | E18: 45300 | F18: 1721.41 | G18: GBP | H18: Open | I18: 0 | L18: 406 | O18: Net 30 | P18: AP | Q18: =IF(Table4[[#This Row],[DaysLate]]="","NA",IF(Table4[[#This Row],[DaysLate]]<=0,"On Time",IF(Table4[[#This Row],[DaysLate]]<=30,"1-30 Days",IF(Table4[[#This Row],[DaysLate]]<=60,"30-60 Days",IF(Table4[[#This Row],[DaysLate]]<=90,"60-90 Days","90+ Days"))))) -> NA | R18: =IF(Table4[[#This Row],[DaysLate]]="","",IF(Table4[[#This Row],[DaysLate]]>0,1,0)) | S18: =IF(Table4[[#This Row],[DisputedFlag]]="","",IF(Table4[[#This Row],[DisputedFlag]]="Yes",1,0)) | T18: =IF(Table4[[#This Row],[PaymentStatus]]="Open",1,0) -> 1 | U18: =IF(Table4[[#This Row],[InvoiceDate]]<>"",YEAR(Table4[[#This Row],[InvoiceDate]]),"") -> 2023
A19: AP10017 | B19: Payable | C19: Global Office | D19: 45656 | E19: 45686 | F19: 2941.63 | G19: USD | H19: Open | I19: 0 | L19: 818 | O19: Net 30 | P19: AP | Q19: =IF(Table4[[#This Row],[DaysLate]]="","NA",IF(Table4[[#This Row],[DaysLate]]<=0,"On Time",IF(Table4[[#This Row],[DaysLate]]<=30,"1-30 Days",IF(Table4[[#This Row],[DaysLate]]<=60,"30-60 Days",IF(Table4[[#This Row],[DaysLate]]<=90,"60-90 Days","90+ Days"))))) -> NA | R19: =IF(Table4[[#This Row],[DaysLate]]="","",IF(Table4[[#This Row],[DaysLate]]>0,1,0)) | S19: =IF(Table4[[#This Row],[DisputedFlag]]="","",IF(Table4[[#This Row],[DisputedFlag]]="Yes",1,0)) | T19: =IF(Table4[[#This Row],[PaymentStatus]]="Open",1,0) -> 1 | U19: =IF(Table4[[#This Row],[InvoiceDate]]<>"",YEAR(Table4[[#This Row],[InvoiceDate]]),"") -> 2024
A20: AP10018 | B20: Payable | C20: Fast Travel | D20: 45470 | E20: 45500 | F20: 889.44 | G20: USD | H20: Paid | I20: 45500 | J20: 0 | L20: 391 | O20: Net 30 | P20: AP | Q20: =IF(Table4[[#This Row],[DaysLate]]="","NA",IF(Table4[[#This Row],[DaysLate]]<=0,"On Time",IF(Table4[[#This Row],[DaysLate]]<=30,"1-30 Days",IF(Table4[[#This Row],[DaysLate]]<=60,"30-60 Days",IF(Table4[[#This Row],[DaysLate]]<=90,"60-90 Days","90+ Days"))))) -> On Time | R20: =IF(Table4[[#This Row],[DaysLate]]="","",IF(Table4[[#This Row],[DaysLate]]>0,1,0)) -> 0 | S20: =IF(Table4[[#This Row],[DisputedFlag]]="","",IF(Table4[[#This Row],[DisputedFlag]]="Yes",1,0)) | T20: =IF(Table4[[#This Row],[PaymentStatus]]="Open",1,0) -> 0 | U20: =IF(Table4[[#This Row],[InvoiceDate]]<>"",YEAR(Table4[[#This Row],[InvoiceDate]]),"") -> 2024
A21: AP10019 | B21: Payable | C21: Fast Travel | D21: 45744 | E21: 45774 | F21: 1539.53 | G21: AUD | H21: Partial | I21: 0 | L21: 897 | O21: Net 30 | P21: AP | Q21: =IF(Table4[[#This Row],[DaysLate]]="","NA",IF(Table4[[#This Row],[DaysLate]]<=0,"On Time",IF(Table4[[#This Row],[DaysLate]]<=30,"1-30 Days",IF(Table4[[#This Row],[DaysLate]]<=60,"30-60 Days",IF(Table4[[#This Row],[DaysLate]]<=90,"60-90 Days","90+ Days"))))) -> NA | R21: =IF(Table4[[#This Row],[DaysLate]]="","",IF(Table4[[#This Row],[DaysLate]]>0,1,0)) | S21: =IF(Table4[[#This Row],[DisputedFlag]]="","",IF(Table4[[#This Row],[DisputedFlag]]="Yes",1,0)) | T21: =IF(Table4[[#This Row],[PaymentStatus]]="Open",1,0) -> 0 | U21: =IF(Table4[[#This Row],[InvoiceDate]]<>"",YEAR(Table4[[#This Row],[InvoiceDate]]),"") -> 2025
A22: AP10020 | B22: Payable | C22: TechMart | D22: 45121 | E22: 45151 | F22: 996.27 | G22: AUD | H22: Open | I22: 0 | L22: 818 | O22: Net 30 | P22: AP | Q22: =IF(Table4[[#This Row],[DaysLate]]="","NA",IF(Table4[[#This Row],[DaysLate]]<=0,"On Time",IF(Table4[[#This Row],[DaysLate]]<=30,"1-30 Days",IF(Table4[[#This Row],[DaysLate]]<=60,"30-60 Days",IF(Table4[[#This Row],[DaysLate]]<=90,"60-90 Days","90+ Days"))))) -> NA | R22: =IF(Table4[[#This Row],[DaysLate]]="","",IF(Table4[[#This Row],[DaysLate]]>0,1,0)) | S22: =IF(Table4[[#This Row],[DisputedFlag]]="","",IF(Table4[[#This Row],[DisputedFlag]]="Yes",1,0)) | T22: =IF(Table4[[#This Row],[PaymentStatus]]="Open",1,0) -> 1 | U22: =IF(Table4[[#This Row],[InvoiceDate]]<>"",YEAR(Table4[[#This Row],[InvoiceDate]]),"") -> 2023
A23: AP10021 | B23: Payable | C23: TechMart | D23: 45105 | E23: 45135 | F23: 2450.1 | G23: CAD | H23: Partial | I23: 0 | L23: 391 | O23: Net 30 | P23: AP | Q23: =IF(Table4[[#This Row],[DaysLate]]="","NA",IF(Table4[[#This Row],[DaysLate]]<=0,"On Time",IF(Table4[[#This Row],[DaysLate]]<=30,"1-30 Days",IF(Table4[[#This Row],[DaysLate]]<=60,"30-60 Days",IF(Table4[[#This Row],[DaysLate]]<=90,"60-90 Days","90+ Days"))))) -> NA | R23: =IF(Table4[[#This Row],[DaysLate]]="","",IF(Table4[[#This Row],[DaysLate]]>0,1,0)) | S23: =IF(Table4[[#This Row],[DisputedFlag]]="","",IF(Table4[[#This Row],[DisputedFlag]]="Yes",1,0)) | T23: =IF(Table4[[#This Row],[PaymentStatus]]="Open",1,0) -> 0 | U23: =IF(Table4[[#This Row],[InvoiceDate]]<>"",YEAR(Table4[[#This Row],[InvoiceDate]]),"") -> 2023
A24: AP10022 | B24: Payable | C24: Global Office | D24: 45653 | E24: 45683 | F24: 797.8 | G24: CAD | H24: Open | I24: 0 | L24: 897 | O24: Net 30 | P24: AP | Q24: =IF(Table4[[#This Row],[DaysLate]]="","NA",IF(Table4[[#This Row],[DaysLate]]<=0,"On Time",IF(Table4[[#This Row],[DaysLate]]<=30,"1-30 Days",IF(Table4[[#This Row],[DaysLate]]<=60,"30-60 Days",IF(Table4[[#This Row],[DaysLate]]<=90,"60-90 Days","90+ Days"))))) -> NA | R24: =IF(Table4[[#This Row],[DaysLate]]="","",IF(Table4[[#This Row],[DaysLate]]>0,1,0)) | S24: =IF(Table4[[#This Row],[DisputedFlag]]="","",IF(Table4[[#This Row],[DisputedFlag]]="Yes",1,0)) | T24: =IF(Table4[[#This Row],[PaymentStatus]]="Open",1,0) -> 1 | U24: =IF(Table4[[#This Row],[InvoiceDate]]<>"",YEAR(Table4[[#This Row],[InvoiceDate]]),"") -> 2024
A25: AP10023 | B25: Payable | C25: BluePrints | D25: 45062 | E25: 45092 | F25: 4237.65 | G25: GBP | H25: Partial | I25: 0 | L25: 770 | O25: Net 30 | P25: AP | Q25: =IF(Table4[[#This Row],[DaysLate]]="","NA",IF(Table4[[#This Row],[DaysLate]]<=0,"On Time",IF(Table4[[#This Row],[DaysLate]]<=30,"1-30 Days",IF(Table4[[#This Row],[DaysLate]]<=60,"30-60 Days",IF(Table4[[#This Row],[DaysLate]]<=90,"60-90 Days","90+ Days"))))) -> NA | R25: =IF(Table4[[#This Row],[DaysLate]]="","",IF(Table4[[#This Row],[DaysLate]]>0,1,0)) | S25: =IF(Table4[[#This Row],[DisputedFlag]]="","",IF(Table4[[#This Row],[DisputedFlag]]="Yes",1,0)) | T25: =IF(Table4[[#This Row],[PaymentStatus]]="Open",1,0) -> 0 | U25: =IF(Table4[[#This Row],[InvoiceDate]]<>"",YEAR(Table4[[#This Row],[InvoiceDate]]),"") -> 2023
A26: AP10024 | B26: Payable | C26: Global Office | D26: 45199 | E26: 45229 | F26: 665.06 | G26: AUD | H26: Open | I26: 0 | L26: 406 | O26: Net 30 | P26: AP | Q26: =IF(Table4[[#This Row],[DaysLate]]="","NA",IF(Table4[[#This Row],[DaysLate]]<=0,"On Time",IF(Table4[[#This Row],[DaysLate]]<=30,"1-30 Days",IF(Table4[[#This Row],[DaysLate]]<=60,"30-60 Days",IF(Table4[[#This Row],[DaysLate]]<=90,"60-90 Days","90+ Days"))))) -> NA | R26: =IF(Table4[[#This Row],[DaysLate]]="","",IF(Table4[[#This Row],[DaysLate]]>0,1,0)) | S26: =IF(Table4[[#This Row],[DisputedFlag]]="","",IF(Table4[[#This Row],[DisputedFlag]]="Yes",1,0)) | T26: =IF(Table4[[#This Row],[PaymentStatus]]="Open",1,0) -> 1 | U26: =IF(Table4[[#This Row],[InvoiceDate]]<>"",YEAR(Table4[[#This Row],[InvoiceDate]]),"") -> 2023
A27: AP10025 | B27: Payable | C27: Global Office | D27: 45640 | E27: 45670 | F27: 3849.16 | G27: GBP | H27: Partial | I27: 0 | L27: 770 | O27: Net 30 | P27: AP | Q27: =IF(Table4[[#This Row],[DaysLate]]="","NA",IF(Table4[[#This Row],[DaysLate]]<=0,"On Time",IF(Table4[[#This Row],[DaysLate]]<=30,"1-30 Days",IF(Table4[[#This Row],[DaysLate]]<=60,"30-60 Days",IF(Table4[[#This Row],[DaysLate]]<=90,"60-90 Days","90+ Days"))))) -> NA | R27: =IF(Table4[[#This Row],[DaysLate]]="","",IF(Table4[[#This Row],[DaysLate]]>0,1,0)) | S27: =IF(Table4[[#This Row],[DisputedFlag]]="","",IF(Table4[[#This Row],[DisputedFlag]]="Yes",1,0)) | T27: =IF(Table4[[#This Row],[PaymentStatus]]="Open",1,0) -> 0 | U27: =IF(Table4[[#This Row],[InvoiceDate]]<>"",YEAR(Table4[[#This Row],[InvoiceDate]]),"") -> 2024
A28: AP10026 | B28: Payable | C28: BluePrints | D28: 45124 | E28: 45154 | F28: 4411.88 | G28: CAD | H28: Paid | I28: 45154 | J28: 0 | L28: 818 | O28: Net 30 | P28: AP | Q28: =IF(Table4[[#This Row],[DaysLate]]="","NA",IF(Table4[[#This Row],[DaysLate]]<=0,"On Time",IF(Table4[[#This Row],[DaysLate]]<=30,"1-30 Days",IF(Table4[[#This Row],[DaysLate]]<=60,"30-60 Days",IF(Table4[[#This Row],[DaysLate]]<=90,"60-90 Days","90+ Days"))))) -> On Time | R28: =IF(Table4[[#This Row],[DaysLate]]="","",IF(Table4[[#This Row],[DaysLate]]>0,1,0)) -> 0 | S28: =IF(Table4[[#This Row],[DisputedFlag]]="","",IF(Table4[[#This Row],[DisputedFlag]]="Yes",1,0)) | T28: =IF(Table4[[#This Row],[PaymentStatus]]="Open",1,0) -> 0 | U28: =IF(Table4[[#This Row],[InvoiceDate]]<>"",YEAR(Table4[[#This Row],[InvoiceDate]]),"") -> 2023
A29: AP10027 | B29: Payable | C29: Fast Travel | D29: 45376 | E29: 45406 | F29: 296.65 | G29: USD | H29: Paid | I29: 45411 | J29: 5 | L29: 406 | O29: Net 30 | P29: AP | Q29: =IF(Table4[[#This Row],[DaysLate]]="","NA",IF(Table4[[#This Row],[DaysLate]]<=0,"On Time",IF(Table4[[#This Row],[DaysLate]]<=30,"1-30 Days",IF(Table4[[#This Row],[DaysLate]]<=60,"30-60 Days",IF(Table4[[#This Row],[DaysLate]]<=90,"60-90 Days","90+ Days"))))) -> 1-30 Days | R29: =IF(Table4[[#This Row],[DaysLate]]="","",IF(Table4[[#This Row],[DaysLate]]>0,1,0)) -> 1 | S29: =IF(Table4[[#This Row],[DisputedFlag]]="","",IF(Table4[[#This Row],[DisputedFlag]]="Yes",1,0)) | T29: =IF(Table4[[#This Row],[PaymentStatus]]="Open",1,0) -> 0 | U29: =IF(Table4[[#This Row],[InvoiceDate]]<>"",YEAR(Table4[[#This Row],[InvoiceDate]]),"") -> 2024
A30: AP10028 | B30: Payable | C30: TechMart | D30: 45593 | E30: 45623 | F30: 3099.8 | G30: GBP | H30: Open | I30: 0 | L30: 391 | O30: Net 30 | P30: AP | Q30: =IF(Table4[[#This Row],[DaysLate]]="","NA",IF(Table4[[#This Row],[DaysLate]]<=0,"On Time",IF(Table4[[#This Row],[DaysLate]]<=30,"1-30 Days",IF(Table4[[#This Row],[DaysLate]]<=60,"30-60 Days",IF(Table4[[#This Row],[DaysLate]]<=90,"60-90 Days","90+ Days"))))) -> NA | R30: =IF(Table4[[#This Row],[DaysLate]]="","",IF(Table4[[#This Row],[DaysLate]]>0,1,0)) | S30: =IF(Table4[[#This Row],[DisputedFlag]]="","",IF(Table4[[#This Row],[DisputedFlag]]="Yes",1,0)) | T30: =IF(Table4[[#This Row],[PaymentStatus]]="Open",1,0) -> 1 | U30: =IF(Table4[[#This Row],[InvoiceDate]]<>"",YEAR(Table4[[#This Row],[InvoiceDate]]),"") -> 2024
A31: AP10029 | B31: Payable | C31: Global Office | D31: 44991 | E31: 45021 | F31: 4007.29 | G31: CAD | H31: Open | I31: 0 | L31: 897 | O31: Net 30 | P31: AP | Q31: =IF(Table4[[#This Row],[DaysLate]]="","NA",IF(Table4[[#This Row],[DaysLate]]<=0,"On Time",IF(Table4[[#This Row],[DaysLate]]<=30,"1-30 Days",IF(Table4[[#This Row],[DaysLate]]<=60,"30-60 Days",IF(Table4[[#This Row],[DaysLate]]<=90,"60-90 Days","90+ Days"))))) -> NA | R31: =IF(Table4[[#This Row],[DaysLate]]="","",IF(Table4[[#This Row],[DaysLate]]>0,1,0)) | S31: =IF(Table4[[#This Row],[DisputedFlag]]="","",IF(Table4[[#This Row],[DisputedFlag]]="Yes",1,0)) | T31: =IF(Table4[[#This Row],[PaymentStatus]]="Open",1,0) -> 1 | U31: =IF(Table4[[#This Row],[InvoiceDate]]<>"",YEAR(Table4[[#This Row],[InvoiceDate]]),"") -> 2023
A32: AP10030 | B32: Payable | C32: Fast Travel | D32: 45335 | E32: 45365 | F32: 2884.32 | G32: CAD | H32: Partial | I32: 0 | L32: 897 | O32: Net 30 | P32: AP | Q32: =IF(Table4[[#This Row],[DaysLate]]="","NA",IF(Table4[[#This Row],[DaysLate]]<=0,"On Time",IF(Table4[[#This Row],[DaysLate]]<=30,"1-30 Days",IF(Table4[[#This Row],[DaysLate]]<=60,"30-60 Days",IF(Table4[[#This Row],[DaysLate]]<=90,"60-90 Days","90+ Days"))))) -> NA | R32: =IF(Table4[[#This Row],[DaysLate]]="","",IF(Table4[[#This Row],[DaysLate]]>0,1,0)) | S32: =IF(Table4[[#This Row],[DisputedFlag]]="","",IF(Table4[[#This Row],[DisputedFlag]]="Yes",1,0)) | T32: =IF(Table4[[#This Row],[PaymentStatus]]="Open",1,0) -> 0 | U32: =IF(Table4[[#This Row],[InvoiceDate]]<>"",YEAR(Table4[[#This Row],[InvoiceDate]]),"") -> 2024
A33: AP10031 | B33: Payable | C33: Fast Travel | D33: 45000 | E33: 45030 | F33: 4830.24 | G33: EUR | H33: Paid | I33: 45030 | J33: 0 | L33: 818 | O33: Net 30 | P33: AP | Q33: =IF(Table4[[#This Row],[DaysLate]]="","NA",IF(Table4[[#This Row],[DaysLate]]<=0,"On Time",IF(Table4[[#This Row],[DaysLate]]<=30,"1-30 Days",IF(Table4[[#This Row],[DaysLate]]<=60,"30-60 Days",IF(Table4[[#This Row],[DaysLate]]<=90,"60-90 Days","90+ Days"))))) -> On Time | R33: =IF(Table4[[#This Row],[DaysLate]]="","",IF(Table4[[#This Row],[DaysLate]]>0,1,0)) -> 0 | S33: =IF(Table4[[#This Row],[DisputedFlag]]="","",IF(Table4[[#This Row],[DisputedFlag]]="Yes",1,0)) | T33: =IF(Table4[[#This Row],[PaymentStatus]]="Open",1,0) -> 0 | U33: =IF(Table4[[#This Row],[InvoiceDate]]<>"",YEAR(Table4[[#This Row],[InvoiceDate]]),"") -> 2023
A34: AP10032 | B34: Payable | C34: Global Office | D34: 45210 | E34: 45240 | F34: 4841.22 | G34: USD | H34: Paid | I34: 45240 | J34: 0 | L34: 406 | O34: Net 30 | P34: AP | Q34: =IF(Table4[[#This Row],[DaysLate]]="","NA",IF(Table4[[#This Row],[DaysLate]]<=0,"On Time",IF(Table4[[#This Row],[DaysLate]]<=30,"1-30 Days",IF(Table4[[#This Row],[DaysLate]]<=60,"30-60 Days",IF(Table4[[#This Row],[DaysLate]]<=90,"60-90 Days","90+ Days"))))) -> On Time | R34: =IF(Table4[[#This Row],[DaysLate]]="","",IF(Table4[[#This Row],[DaysLate]]>0,1,0)) -> 0 | S34: =IF(Table4[[#This Row],[DisputedFlag]]="","",IF(Table4[[#This Row],[DisputedFlag]]="Yes",1,0)) | T34: =IF(Table4[[#This Row],[PaymentStatus]]="Open",1,0) -> 0 | U34: =IF(Table4[[#This Row],[InvoiceDate]]<>"",YEAR(Table4[[#This Row],[InvoiceDate]]),"") -> 2023
A35: AP10033 | B35: Payable | C35: ABC Supplies | D35: 45598 | E35: 45628 | F35: 3601.17 | G35: AUD | H35: Open | I35: 0 | L35: 391 | O35: Net 30 | P35: AP | Q35: =IF(Table4[[#This Row],[DaysLate]]="","NA",IF(Table4[[#This Row],[DaysLate]]<=0,"On Time",IF(Table4[[#This Row],[DaysLate]]<=30,"1-30 Days",IF(Table4[[#This Row],[DaysLate]]<=60,"30-60 Days",IF(Table4[[#This Row],[DaysLate]]<=90,"60-90 Days","90+ Days"))))) -> NA | R35: =IF(Table4[[#This Row],[DaysLate]]="","",IF(Table4[[#This Row],[DaysLate]]>0,1,0)) | S35: =IF(Table4[[#This Row],[DisputedFlag]]="","",IF(Table4[[#This Row],[DisputedFlag]]="Yes",1,0)) | T35: =IF(Table4[[#This Row],[PaymentStatus]]="Open",1,0) -> 1 | U35: =IF(Table4[[#This Row],[InvoiceDate]]<>"",YEAR(Table4[[#This Row],[InvoiceDate]]),"") -> 2024
A36: AP10034 | B36: Payable | C36: Fast Travel | D36: 45668 | E36: 45698 | F36: 3913.65 | G36: GBP | H36: Paid | I36: 45698 | J36: 0 | L36: 770 | O36: Net 30 | P36: AP | Q36: =IF(Table4[[#This Row],[DaysLate]]="","NA",IF(Table4[[#This Row],[DaysLate]]<=0,"On Time",IF(Table4[[#This Row],[DaysLate]]<=30,"1-30 Days",IF(Table4[[#This Row],[DaysLate]]<=60,"30-60 Days",IF(Table4[[#This Row],[DaysLate]]<=90,"60-90 Days","90+ Days"))))) -> On Time | R36: =IF(Table4[[#This Row],[DaysLate]]="","",IF(Table4[[#This Row],[DaysLate]]>0,1,0)) -> 0 | S36: =IF(Table4[[#This Row],[DisputedFlag]]="","",IF(Table4[[#This Row],[DisputedFlag]]="Yes",1,0)) | T36: =IF(Table4[[#This Row],[PaymentStatus]]="Open",1,0) -> 0 | U36: =IF(Table4[[#This Row],[InvoiceDate]]<>"",YEAR(Table4[[#This Row],[InvoiceDate]]),"") -> 2025
A37: AP10035 | B37: Payable | C37: ABC Supplies | D37: 45025 | E37: 45055 | F37: 1117.52 | G37: CAD | H37: Open | I37: 0 | L37: 770 | O37: Net 30 | P37: AP | Q37: =IF(Table4[[#This Row],[DaysLate]]="","NA",IF(Table4[[#This Row],[DaysLate]]<=0,"On Time",IF(Table4[[#This Row],[DaysLate]]<=30,"1-30 Days",IF(Table4[[#This Row],[DaysLate]]<=60,"30-60 Days",IF(Table4[[#This Row],[DaysLate]]<=90,"60-90 Days","90+ Days"))))) -> NA | R37: =IF(Table4[[#This Row],[DaysLate]]="","",IF(Table4[[#This Row],[DaysLate]]>0,1,0)) | S37: =IF(Table4[[#This Row],[DisputedFlag]]="","",IF(Table4[[#This Row],[DisputedFlag]]="Yes",1,0)) | T37: =IF(Table4[[#This Row],[PaymentStatus]]="Open",1,0) -> 1 | U37: =IF(Table4[[#This Row],[InvoiceDate]]<>"",YEAR(Table4[[#This Row],[InvoiceDate]]),"") -> 2023
A38: AP10036 | B38: Payable | C38: BluePrints | D38: 45128 | E38: 45158 | F38: 4178.2 | G38: CAD | H38: Partial | I38: 0 | L38: 391 | O38: Net 30 | P38: AP | Q38: =IF(Table4[[#This Row],[DaysLate]]="","NA",IF(Table4[[#This Row],[DaysLate]]<=0,"On Time",IF(Table4[[#This Row],[DaysLate]]<=30,"1-30 Days",IF(Table4[[#This Row],[DaysLate]]<=60,"30-60 Days",IF(Table4[[#This Row],[DaysLate]]<=90,"60-90 Days","90+ Days"))))) -> NA | R38: =IF(Table4[[#This Row],[DaysLate]]="","",IF(Table4[[#This Row],[DaysLate]]>0,1,0)) | S38: =IF(Table4[[#This Row],[DisputedFlag]]="","",IF(Table4[[#This Row],[DisputedFlag]]="Yes",1,0)) | T38: =IF(Table4[[#This Row],[PaymentStatus]]="Open",1,0) -> 0 | U38: =IF(Table4[[#This Row],[InvoiceDate]]<>"",YEAR(Table4[[#This Row],[InvoiceDate]]),"") -> 2023
A39: AP10037 | B39: Payable | C39: Global Office | D39: 45504 | E39: 45534 | F39: 504.02 | G39: USD | H39: Partial | I39: 0 | L39: 406 | O39: Net 30 | P39: AP | Q39: =IF(Table4[[#This Row],[DaysLate]]="","NA",IF(Table4[[#This Row],[DaysLate]]<=0,"On Time",IF(Table4[[#This Row],[DaysLate]]<=30,"1-30 Days",IF(Table4[[#This Row],[DaysLate]]<=60,"30-60 Days",IF(Table4[[#This Row],[DaysLate]]<=90,"60-90 Days","90+ Days"))))) -> NA | R39: =IF(Table4[[#This Row],[DaysLate]]="","",IF(Table4[[#This Row],[DaysLate]]>0,1,0)) | S39: =IF(Table4[[#This Row],[DisputedFlag]]="","",IF(Table4[[#This Row],[DisputedFlag]]="Yes",1,0)) | T39: =IF(Table4[[#This Row],[PaymentStatus]]="Open",1,0) -> 0 | U39: =IF(Table4[[#This Row],[InvoiceDate]]<>"",YEAR(Table4[[#This Row],[InvoiceDate]]),"") -> 2024
A40: AP10038 | B40: Payable | C40: BluePrints | D40: 44934 | E40: 44964 | F40: 3156.05 | G40: GBP | H40: Open | I40: 0 | L40: 818 | O40: Net 30 | P40: AP | Q40: =IF(Table4[[#This Row],[DaysLate]]="","NA",IF(Table4[[#This Row],[DaysLate]]<=0,"On Time",IF(Table4[[#This Row],[DaysLate]]<=30,"1-30 Days",IF(Table4[[#This Row],[DaysLate]]<=60,"30-60 Days",IF(Table4[[#This Row],[DaysLate]]<=90,"60-90 Days","90+ Days"))))) -> NA | R40: =IF(Table4[[#This Row],[DaysLate]]="","",IF(Table4[[#This Row],[DaysLate]]>0,1,0)) | S40: =IF(Table4[[#This Row],[DisputedFlag]]="","",IF(Table4[[#This Row],[DisputedFlag]]="Yes",1,0)) | T40: =IF(Table4[[#This Row],[PaymentStatus]]="Open",1,0) -> 1 | U40: =IF(Table4[[#This Row],[InvoiceDate]]<>"",YEAR(Table4[[#This Row],[InvoiceDate]]),"") -> 2023
...

Sheet AR_Raw
A1: countryCode | B1: customerID | C1: PaperlessDate | D1: invoiceNumber | E1: InvoiceDate | F1: DueDate | G1: InvoiceAmount | H1: Disputed | I1: SettledDate | J1: PaperlessBill | K1: DaysToSettle | L1: DaysLate
A2: 391 | B2: 0379-NEVHP | C2: 41429 | D2: 611365 | E2: 41306 | F2: 41276 | G2: 55.94 | H2: No | I2: 41306 | J2: Paper | K2: 13 | L2: 0
A3: 406 | B3: 8976-AMJEO | C3: 40971 | D3: 7900770 | E3: 41300 | F3: 41330 | G3: 61.74 | H3: Yes | I3: 41300 | J3: Electronic | K3: 36 | L3: 0
A4: 391 | B4: 2820-XGXSB | C4: 40934 | D4: 9231909 | E4: 41340 | F4: 41313 | G4: 65.88 | H4: No | I4: 41340 | J4: Electronic | K4: 5 | L4: 0
A5: 406 | B5: 9322-YCTQO | C5: 41064 | D5: 9888306 | E5: 41549 | F5: 41611 | G5: 105.92 | H5: No | I5: 41549 | J5: Electronic | K5: 35 | L5: 5
A6: 818 | B6: 6627-ELFBK | C6: 41239 | D6: 15752855 | E6: 41207 | F6: 41237 | G6: 72.27 | H6: Yes | I6: 41207 | J6: Paper | K6: 34 | L6: 4
A7: 818 | B7: 5148-SYKLB | C7: 41514 | D7: 18104516 | E7: 40935 | F7: 40965 | G7: 94 | H7: Yes | I7: 40935 | J7: Paper | K7: 26 | L7: 0
A8: 897 | B8: 8690-EEBEO | C8: 41041 | D8: 23864272 | E8: 41499 | F8: 41617 | G8: 74.69 | H8: No | I8: 41499 | J8: Electronic | K8: 27 | L8: 0
A9: 770 | B9: 4460-ZXNDN | C9: 41452 | D9: 27545037 | E9: 41259 | F9: 41289 | G9: 75.06 | H9: No | I9: 41259 | J9: Paper | K9: 27 | L9: 0
A10: 770 | B10: 3831-FXWYK | C10: 41489 | D10: 28049695 | E10: 41043 | F10: 41073 | G10: 80.07 | H10: Yes | I10: 41043 | J10: Paper | K10: 48 | L10: 18
A11: 897 | B11: 7654-DOLHO | C11: 41003 | D11: 32277701 | E11: 41281 | F11: 41486 | G11: 48.33 | H11: No | I11: 41281 | J11: Electronic | K11: 25 | L11: 0
A12: 770 | B12: 3993-QUNVJ | C12: 41274 | D12: 35868002 | E12: 40999 | F12: 41029 | G12: 75.33 | H12: No | I12: 40999 | J12: Paper | K12: 16 | L12: 0
A13: 406 | B13: 5284-DJOZO | C13: 41222 | D13: 36478577 | E13: 41463 | F13: 41434 | G13: 73.35 | H13: No | I13: 41463 | J13: Electronic | K13: 8 | L13: 0
... A2467: 406 | B2467: 9758-AIEIK | C2467: 41022 | D2467: 9990243864 | E2467: 41371 | F2467: 41341 | G2467: 68.66 | H2467: No | I2467: 41371 | J2467: Electronic | K2467: 14 | L2467: 0

Sheet AR_Transformed
A1: TransactionID | B1: TransactionType | C1: PartyName | D1: InvoiceDate | E1: DueDate | F1: Amount | G1: Currency | H1: PaymentStatus | I1: PaidDate | J1: DaysLate | K1: DisputedFlag | L1: Country | M1: PaperlessDate | N1: PaperlessBill | O1: Terms | P1: DatasetSource
A2: 391 | B2: Receivables | C2: 0379-NEVHP | D2: 41306 | E2: 41276 | F2: 55.94 | H2: Paid | I2: 41306 | J2: 0 | K2: No | L2: 391 | M2: 41429 | N2: Paper | P2: AR
A3: 406 | B3: Receivables | C3: 8976-AMJEO | D3: 41300 | E3: 41330 | F3: 61.74 | H3: Paid | I3: 41300 | J3: 0 | K3: Yes | L3: 406 | M3: 40971 | N3: Electronic | P3: AR
A4: 391 | B4: Receivables | C4: 2820-XGXSB | D4: 41340 | E4: 41313 | F4: 65.88 | H4: Paid | I4: 41340 | J4: 0 | K4: No | L4: 391 | M4: 40934 | N4: Electronic | P4: AR
A5: 406 | B5: Receivables | C5: 9322-YCTQO | D5: 41549 | E5: 41611 | F5: 105.92 | H5: Paid | I5: 41549 | J5: 5 | K5: No | L5: 406 | M5: 41064 | N5: Electronic | P5: AR
A6: 818 | B6: Receivables | C6: 6627-ELFBK | D6: 41207 | E6: 41237 | F6: 72.27 | H6: Paid | I6: 41207 | J6: 4 | K6: Yes | L6: 818 | M6: 41239 | N6: Paper | P6: AR
A7: 818 | B7: Receivables | C7: 5148-SYKLB | D7: 40935 | E7: 40965 | F7: 94 | H7: Paid | I7: 40935 | J7: 0 | K7: Yes | L7: 818 | M7: 41514 | N7: Paper | P7: AR
A8: 897 | B8: Receivables | C8: 8690-EEBEO | D8: 41499 | E8: 41617 | F8: 74.69 | H8: Paid | I8: 41499 | J8: 0 | K8: No | L8: 897 | M8: 41041 | N8: Electronic | P8: AR
A9: 770 | B9: Receivables | C9: 4460-ZXNDN | D9: 41259 | E9: 41289 | F9: 75.06 | H9: Paid | I9: 41259 | J9: 0 | K9: No | L9: 770 | M9: 41452 | N9: Paper | P9: AR
A10: 770 | B10: Receivables | C10: 3831-FXWYK | D10: 41043 | E10: 41073 | F10: 80.07 | H10: Paid | I10: 41043 | J10: 18 | K10: Yes | L10: 770 | M10: 41489 | N10: Paper | P10: AR
A11: 897 | B11: Receivables | C11: 7654-DOLHO | D11: 41281 | E11: 41486 | F11: 48.33 | H11: Paid | I11: 41281 | J11: 0 | K11: No | L11: 897 | M11: 41003 | N11: Electronic | P11: AR
A12: 770 | B12: Receivables | C12: 3993-QUNVJ | D12: 40999 | E12: 41029 | F12: 75.33 | H12: Paid | I12: 40999 | J12: 0 | K12: No | L12: 770 | M12: 41274 | N12: Paper | P12: AR
A13: 406 | B13: Receivables | C13: 5284-DJOZO | D13: 41463 | E13: 41434 | F13: 73.35 | H13: Paid | I13: 41463 | J13: 0 | K13: No | L13: 406 | M13: 41222 | N13: Electronic | P13: AR
... A2467: 406 | B2467: Receivables | C2467: 9758-AIEIK | D2467: 41371 | E2467: 41341 | F2467: 68.66 | H2467: Paid | I2467: 41371 | J2467: 0 | K2467: No | L2467: 406 | M2467: 41022 | N2467: Electronic | P2467: AR

Sheet AP_Raw
A1: APID | B1: Vendor | C1: InvoiceDate | D1: DueDate | E1: Amount | F1: Currency | G1: Status | H1: PaidDate | I1: Terms | J1: Days late
A2: AP10000 | B2: BluePrints | C2: 45642 | D2: 45672 | E2: 344.25 | F2: EUR | G2: Open | I2: Net 30 | J2: =IF(H2<>"",MAX(H2-D2,0),"")
A3: AP10001 | B3: BluePrints | C3: 45430 | D3: 45460 | E3: 3298.38 | F3: CAD | G3: Partial | I3: Net 30 | J3: =IF(H3<>"",MAX(H3-D3,0),"")
A4: AP10002 | B4: Fast Travel | C4: 45347 | D4: 45377 | E4: 1023.43 | F4: GBP | G4: Open | I4: Net 30 | J4: =IF(H4<>"",MAX(H4-D4,0),"")
A5: AP10003 | B5: ABC Supplies | C5: 45299 | D5: 45329 | E5: 4433.05 | F5: USD | G5: Partial | I5: Net 30 | J5: =IF(H5<>"",MAX(H5-D5,0),"")
A6: AP10004 | B6: ABC Supplies | C6: 45435 | D6: 45465 | E6: 4345.14 | F6: GBP | G6: Partial | I6: Net 30 | J6: =IF(H6<>"",MAX(H6-D6,0),"")
A7: AP10005 | B7: Fast Travel | C7: 45482 | D7: 45512 | E7: 1599.18 | F7: AUD | G7: Open | I7: Net 30 | J7: =IF(H7<>"",MAX(H7-D7,0),"")
A8: AP10006 | B8: BluePrints | C8: 45646 | D8: 45676 | E8: 894.13 | F8: USD | G8: Open | I8: Net 30 | J8: =IF(H8<>"",MAX(H8-D8,0),"")
A9: AP10007 | B9: Fast Travel | C9: 45560 | D9: 45590 | E9: 1303.06 | F9: GBP | G9: Paid | H9: 45593 | I9: Net 30 | J9: =IF(H9<>"",MAX(H9-D9,0),"") -> 3
A10: AP10008 | B10: ABC Supplies | C10: 45334 | D10: 45364 | E10: 3481.8 | F10: CAD | G10: Paid | H10: 45367 | I10: Net 30 | J10: =IF(H10<>"",MAX(H10-D10,0),"") -> 3
A11: AP10009 | B11: ABC Supplies | C11: 45470 | D11: 45500 | E11: 217.97 | F11: USD | G11: Open | I11: Net 30 | J11: =IF(H11<>"",MAX(H11-D11,0),"")
A12: AP10010 | B12: BluePrints | C12: 45360 | D12: 45390 | E12: 1809.07 | F12: EUR | G12: Partial | I12: Net 30 | J12: =IF(H12<>"",MAX(H12-D12,0),"")
A13: AP10011 | B13: BluePrints | C13: 45575 | D13: 45605 | E13: 884.1 | F13: USD | G13: Open | I13: Net 30 | J13: =IF(H13<>"",MAX(H13-D13,0),"")
A14: AP10012 | B14: ABC Supplies | C14: 45065 | D14: 45095 | E14: 1491.7 | F14: GBP | G14: Open | I14: Net 30 | J14: =IF(H14<>"",MAX(H14-D14,0),"")
A15: AP10013 | B15: ABC Supplies | C15: 45249 | D15: 45279 | E15: 4212.17 | F15: AUD | G15: Paid | H15: 45285 | I15: Net 30 | J15: =IF(H15<>"",MAX(H15-D15,0),"") -> 6
A16: AP10014 | B16: BluePrints | C16: 45417 | D16: 45447 | E16: 1632.82 | F16: GBP | G16: Open | I16: Net 30 | J16: =IF(H16<>"",MAX(H16-D16,0),"")
A17: AP10015 | B17: BluePrints | C17: 45081 | D17: 45111 | E17: 1887.67 | F17: EUR | G17: Paid | H17: 45111 | I17: Net 30 | J17: =IF(H17<>"",MAX(H17-D17,0),"") -> 0
A18: AP10016 | B18: BluePrints | C18: 45270 | D18: 45300 | E18: 1721.41 | F18: GBP | G18: Open | I18: Net 30 | J18: =IF(H18<>"",MAX(H18-D18,0),"")
A19: AP10017 | B19: Global Office | C19: 45656 | D19: 45686 | E19: 2941.63 | F19: USD | G19: Open | I19: Net 30 | J19: =IF(H19<>"",MAX(H19-D19,0),"")
A20: AP10018 | B20: Fast Travel | C20: 45470 | D20: 45500 | E20: 889.44 | F20: USD | G20: Paid | H20: 45500 | I20: Net 30 | J20: =IF(H20<>"",MAX(H20-D20,0),"") -> 0
A21: AP10019 | B21: Fast Travel | C21: 45744 | D21: 45774 | E21: 1539.53 | F21: AUD | G21: Partial | I21: Net 30 | J21: =IF(H21<>"",MAX(H21-D21,0),"")
A22: AP10020 | B22: TechMart | C22: 45121 | D22: 45151 | E22: 996.27 | F22: AUD | G22: Open | I22: Net 30 | J22: =IF(H22<>"",MAX(H22-D22,0),"")
A23: AP10021 | B23: TechMart | C23: 45105 | D23: 45135 | E23: 2450.1 | F23: CAD | G23: Partial | I23: Net 30 | J23: =IF(H23<>"",MAX(H23-D23,0),"")
A24: AP10022 | B24: Global Office | C24: 45653 | D24: 45683 | E24: 797.8 | F24: CAD | G24: Open | I24: Net 30 | J24: =IF(H24<>"",MAX(H24-D24,0),"")
A25: AP10023 | B25: BluePrints | C25: 45062 | D25: 45092 | E25: 4237.65 | F25: GBP | G25: Partial | I25: Net 30 | J25: =IF(H25<>"",MAX(H25-D25,0),"")
A26: AP10024 | B26: Global Office | C26: 45199 | D26: 45229 | E26: 665.06 | F26: AUD | G26: Open | I26: Net 30 | J26: =IF(H26<>"",MAX(H26-D26,0),"")
A27: AP10025 | B27: Global Office | C27: 45640 | D27: 45670 | E27: 3849.16 | F27: GBP | G27: Partial | I27: Net 30 | J27: =IF(H27<>"",MAX(H27-D27,0),"")
A28: AP10026 | B28: BluePrints | C28: 45124 | D28: 45154 | E28: 4411.88 | F28: CAD | G28: Paid | H28: 45154 | I28: Net 30 | J28: =IF(H28<>"",MAX(H28-D28,0),"") -> 0
A29: AP10027 | B29: Fast Travel | C29: 45376 | D29: 45406 | E29: 296.65 | F29: USD | G29: Paid | H29: 45411 | I29: Net 30 | J29: =IF(H29<>"",MAX(H29-D29,0),"") -> 5
A30: AP10028 | B30: TechMart | C30: 45593 | D30: 45623 | E30: 3099.8 | F30: GBP | G30: Open | I30: Net 30 | J30: =IF(H30<>"",MAX(H30-D30,0),"")
A31: AP10029 | B31: Global Office | C31: 44991 | D31: 45021 | E31: 4007.29 | F31: CAD | G31: Open | I31: Net 30 | J31: =IF(H31<>"",MAX(H31-D31,0),"")
A32: AP10030 | B32: Fast Travel | C32: 45335 | D32: 45365 | E32: 2884.32 | F32: CAD | G32: Partial | I32: Net 30 | J32: =IF(H32<>"",MAX(H32-D32,0),"")
A33: AP10031 | B33: Fast Travel | C33: 45000 | D33: 45030 | E33: 4830.24 | F33: EUR | G33: Paid | H33: 45030 | I33: Net 30 | J33: =IF(H33<>"",MAX(H33-D33,0),"") -> 0
A34: AP10032 | B34: Global Office | C34: 45210 | D34: 45240 | E34: 4841.22 | F34: USD | G34: Paid | H34: 45240 | I34: Net 30 | J34: =IF(H34<>"",MAX(H34-D34,0),"") -> 0
A35: AP10033 | B35: ABC Supplies | C35: 45598 | D35: 45628 | E35: 3601.17 | F35: AUD | G35: Open | I35: Net 30 | J35: =IF(H35<>"",MAX(H35-D35,0),"")
A36: AP10034 | B36: Fast Travel | C36: 45668 | D36: 45698 | E36: 3913.65 | F36: GBP | G36: Paid | H36: 45698 | I36: Net 30 | J36: =IF(H36<>"",MAX(H36-D36,0),"") -> 0
A37: AP10035 | B37: ABC Supplies | C37: 45025 | D37: 45055 | E37: 1117.52 | F37: CAD | G37: Open | I37: Net 30 | J37: =IF(H37<>"",MAX(H37-D37,0),"")
A38: AP10036 | B38: BluePrints | C38: 45128 | D38: 45158 | E38: 4178.2 | F38: CAD | G38: Partial | I38: Net 30 | J38: =IF(H38<>"",MAX(H38-D38,0),"")
A39: AP10037 | B39: Global Office | C39: 45504 | D39: 45534 | E39: 504.02 | F39: USD | G39: Partial | I39: Net 30 | J39: =IF(H39<>"",MAX(H39-D39,0),"")
A40: AP10038 | B40: BluePrints | C40: 44934 | D40: 44964 | E40: 3156.05 | F40: GBP | G40: Open | I40: Net 30 | J40: =IF(H40<>"",MAX(H40-D40,0),"")
...

Sheet AP_Transformed
A1: TransactionID | B1: TransactionType | C1: PartyName | D1: InvoiceDate | E1: DueDate | F1: Amount | G1: Currency | H1: PaymentStatus | I1: PaidDate | J1: DaysLate | K1: DisputedFlag | L1: Country | M1: PaperlessDate | N1: PaperlessBill | O1: Terms | P1: DatasetSource
A2: AP10000 | B2: Payable | C2: BluePrints | D2: 45642 | E2: 45672 | F2: 344.25 | G2: EUR | H2: Open | I2: 0 | O2: Net 30 | P2: AP
A3: AP10001 | B3: Payable | C3: BluePrints | D3: 45430 | E3: 45460 | F3: 3298.38 | G3: CAD | H3: Partial | I3: 0 | O3: Net 30 | P3: AP
A4: AP10002 | B4: Payable | C4: Fast Travel | D4: 45347 | E4: 45377 | F4: 1023.43 | G4: GBP | H4: Open | I4: 0 | O4: Net 30 | P4: AP
A5: AP10003 | B5: Payable | C5: ABC Supplies | D5: 45299 | E5: 45329 | F5: 4433.05 | G5: USD | H5: Partial | I5: 0 | O5: Net 30 | P5: AP
A6: AP10004 | B6: Payable | C6: ABC Supplies | D6: 45435 | E6: 45465 | F6: 4345.14 | G6: GBP | H6: Partial | I6: 0 | O6: Net 30 | P6: AP
A7: AP10005 | B7: Payable | C7: Fast Travel | D7: 45482 | E7: 45512 | F7: 1599.18 | G7: AUD | H7: Open | I7: 0 | O7: Net 30 | P7: AP
A8: AP10006 | B8: Payable | C8: BluePrints | D8: 45646 | E8: 45676 | F8: 894.13 | G8: USD | H8: Open | I8: 0 | O8: Net 30 | P8: AP
A9: AP10007 | B9: Payable | C9: Fast Travel | D9: 45560 | E9: 45590 | F9: 1303.06 | G9: GBP | H9: Paid | I9: 45593 | J9: 3 | O9: Net 30 | P9: AP
A10: AP10008 | B10: Payable | C10: ABC Supplies | D10: 45334 | E10: 45364 | F10: 3481.8 | G10: CAD | H10: Paid | I10: 45367 | J10: 3 | O10: Net 30 | P10: AP
A11: AP10009 | B11: Payable | C11: ABC Supplies | D11: 45470 | E11: 45500 | F11: 217.97 | G11: USD | H11: Open | I11: 0 | O11: Net 30 | P11: AP
A12: AP10010 | B12: Payable | C12: BluePrints | D12: 45360 | E12: 45390 | F12: 1809.07 | G12: EUR | H12: Partial | I12: 0 | O12: Net 30 | P12: AP
A13: AP10011 | B13: Payable | C13: BluePrints | D13: 45575 | E13: 45605 | F13: 884.1 | G13: USD | H13: Open | I13: 0 | O13: Net 30 | P13: AP
A14: AP10012 | B14: Payable | C14: ABC Supplies | D14: 45065 | E14: 45095 | F14: 1491.7 | G14: GBP | H14: Open | I14: 0 | O14: Net 30 | P14: AP
A15: AP10013 | B15: Payable | C15: ABC Supplies | D15: 45249 | E15: 45279 | F15: 4212.17 | G15: AUD | H15: Paid | I15: 45285 | J15: 6 | O15: Net 30 | P15: AP
A16: AP10014 | B16: Payable | C16: BluePrints | D16: 45417 | E16: 45447 | F16: 1632.82 | G16: GBP | H16: Open | I16: 0 | O16: Net 30 | P16: AP
A17: AP10015 | B17: Payable | C17: BluePrints | D17: 45081 | E17: 45111 | F17: 1887.67 | G17: EUR | H17: Paid | I17: 45111 | J17: 0 | O17: Net 30 | P17: AP
A18: AP10016 | B18: Payable | C18: BluePrints | D18: 45270 | E18: 45300 | F18: 1721.41 | G18: GBP | H18: Open | I18: 0 | O18: Net 30 | P18: AP
A19: AP10017 | B19: Payable | C19: Global Office | D19: 45656 | E19: 45686 | F19: 2941.63 | G19: USD | H19: Open | I19: 0 | O19: Net 30 | P19: AP
A20: AP10018 | B20: Payable | C20: Fast Travel | D20: 45470 | E20: 45500 | F20: 889.44 | G20: USD | H20: Paid | I20: 45500 | J20: 0 | O20: Net 30 | P20: AP
A21: AP10019 | B21: Payable | C21: Fast Travel | D21: 45744 | E21: 45774 | F21: 1539.53 | G21: AUD | H21: Partial | I21: 0 | O21: Net 30 | P21: AP
A22: AP10020 | B22: Payable | C22: TechMart | D22: 45121 | E22: 45151 | F22: 996.27 | G22: AUD | H22: Open | I22: 0 | O22: Net 30 | P22: AP
A23: AP10021 | B23: Payable | C23: TechMart | D23: 45105 | E23: 45135 | F23: 2450.1 | G23: CAD | H23: Partial | I23: 0 | O23: Net 30 | P23: AP
A24: AP10022 | B24: Payable | C24: Global Office | D24: 45653 | E24: 45683 | F24: 797.8 | G24: CAD | H24: Open | I24: 0 | O24: Net 30 | P24: AP
A25: AP10023 | B25: Payable | C25: BluePrints | D25: 45062 | E25: 45092 | F25: 4237.65 | G25: GBP | H25: Partial | I25: 0 | O25: Net 30 | P25: AP
A26: AP10024 | B26: Payable | C26: Global Office | D26: 45199 | E26: 45229 | F26: 665.06 | G26: AUD | H26: Open | I26: 0 | O26: Net 30 | P26: AP
A27: AP10025 | B27: Payable | C27: Global Office | D27: 45640 | E27: 45670 | F27: 3849.16 | G27: GBP | H27: Partial | I27: 0 | O27: Net 30 | P27: AP
A28: AP10026 | B28: Payable | C28: BluePrints | D28: 45124 | E28: 45154 | F28: 4411.88 | G28: CAD | H28: Paid | I28: 45154 | J28: 0 | O28: Net 30 | P28: AP
A29: AP10027 | B29: Payable | C29: Fast Travel | D29: 45376 | E29: 45406 | F29: 296.65 | G29: USD | H29: Paid | I29: 45411 | J29: 5 | O29: Net 30 | P29: AP
A30: AP10028 | B30: Payable | C30: TechMart | D30: 45593 | E30: 45623 | F30: 3099.8 | G30: GBP | H30: Open | I30: 0 | O30: Net 30 | P30: AP
A31: AP10029 | B31: Payable | C31: Global Office | D31: 44991 | E31: 45021 | F31: 4007.29 | G31: CAD | H31: Open | I31: 0 | O31: Net 30 | P31: AP
A32: AP10030 | B32: Payable | C32: Fast Travel | D32: 45335 | E32: 45365 | F32: 2884.32 | G32: CAD | H32: Partial | I32: 0 | O32: Net 30 | P32: AP
A33: AP10031 | B33: Payable | C33: Fast Travel | D33: 45000 | E33: 45030 | F33: 4830.24 | G33: EUR | H33: Paid | I33: 45030 | J33: 0 | O33: Net 30 | P33: AP
A34: AP10032 | B34: Payable | C34: Global Office | D34: 45210 | E34: 45240 | F34: 4841.22 | G34: USD | H34: Paid | I34: 45240 | J34: 0 | O34: Net 30 | P34: AP
A35: AP10033 | B35: Payable | C35: ABC Supplies | D35: 45598 | E35: 45628 | F35: 3601.17 | G35: AUD | H35: Open | I35: 0 | O35: Net 30 | P35: AP
A36: AP10034 | B36: Payable | C36: Fast Travel | D36: 45668 | E36: 45698 | F36: 3913.65 | G36: GBP | H36: Paid | I36: 45698 | J36: 0 | O36: Net 30 | P36: AP
A37: AP10035 | B37: Payable | C37: ABC Supplies | D37: 45025 | E37: 45055 | F37: 1117.52 | G37: CAD | H37: Open | I37: 0 | O37: Net 30 | P37: AP
A38: AP10036 | B38: Payable | C38: BluePrints | D38: 45128 | E38: 45158 | F38: 4178.2 | G38: CAD | H38: Partial | I38: 0 | O38: Net 30 | P38: AP
A39: AP10037 | B39: Payable | C39: Global Office | D39: 45504 | E39: 45534 | F39: 504.02 | G39: USD | H39: Partial | I39: 0 | O39: Net 30 | P39: AP
A40: AP10038 | B40: Payable | C40: BluePrints | D40: 44934 | E40: 44964 | F40: 3156.05 | G40: GBP | H40: Open | I40: 0 | O40: Net 30 | P40: AP
...

Sheet Pivot_AgingSummary
A3: Row Labels | B3: Sum of Amount | C3: Count of TransactionID
A4: 1-30 Days | B4: 157726.88 | C4: 906
A5: 30-60 Days | B5: 561.52 | C5: 8
A6: NA | B6: 1418925.6 | C6: 543
A7: On Time | B7: 658011.52 | C7: 1809
A8: Grand Total | B8: 2235225.5 | C8: 3266

Sheet Pivot_LateByYear
A3: Average of Late Flag | B3: Column Labels
A4: Row Labels | B4: Payable | C4: Receivables | D4: Grand Total
A5: 2012 | C5: 0.39075959 | D5: 0.39075959
A6: 2013 | C6: 0.31707317 | D6: 0.31707317
A7: 2023 | B7: 0.11111111 | D7: 0.11111111
A8: 2024 | B8: 0.20212766 | D8: 0.20212766
A9: 2025 | B9: 0.13043478 | D9: 0.13043478
A10: Grand Total | B10: 0.14785992 | C10: 0.35523114 | D10: 0.3356592

Sheet Pivot_Disputed
A1: TransactionType | B1: (All)
A3: Row Labels | B3: Sum of Amount | C3: Count of TransactionID
A4: 0 | B4: 110957.06 | C4: 1905
A5: 1 | B5: 36746.12 | C5: 561
B6: 2087522.3 | C6: 800
A7: Grand Total | B7: 2235225.5 | C7: 3266

Sheet Pivot_OpenAmount
A1: Open | B1: (All)
A3: Row Labels | B3: Sum of Amount
A4: Payable | B4: 2087522.3
A5: Receivables | B5: 147703.18
A6: Grand Total | B6: 2235225.5

Sheet Sheet3
